Workbook

Sheet all_feats_500ns
A1: name | B1: ID | C1: Group | D1: Label | E1: Binder_score | F1: Sequence | G1: Gate mean (A) | H1: Gate SD (A) | I1: Latch mean (A) | J1: Latch SD (A) | K1: Lb7a5 mean (A) | L1: Lb7a5 SD (A) | M1: Recoil mean (A) | N1: Recoil SD (A) | O1: Gate-latch mean (A) | P1: Gate-latch SD (A) | Q1: Closed % (<9.5 A) | R1: Open % (>11.5 A) | S1: Intermediate % | T1: R_58 | U1: R_59 | V1: R_62 | W1: R_83 | X1: R_87 | Y1: R_88 | Z1: R_89 | AA1: R_92 | AB1: R_110 | AC1: R_115 | AD1: R_116 | AE1: R_117 | AF1: R_120 | AG1: R_122 | AH1: R_159 | AI1: R_160 | AJ1: R_163 | AK1: R_164 | AL1: D_30 | AM1: W_30 | AN1: D_32 | AO1: W_32 | AP1: D_33 | AQ1: W_33 | AR1: D_34 | AS1: W_34 | AT1: D_36 | AU1: W_36 | AV1: D_46 | AW1: W_46 | AX1: D_48 | AY1: W_48 | AZ1: D_49 | BA1: W_49 | BB1: D_50 | BC1: W_50 | BD1: D_51 | BE1: W_51 | BF1: D_52 | BG1: W_52 | BH1: D_53 | BI1: W_53 | BJ1: D_54 | BK1: W_54 | BL1: D_55 | BM1: W_55 | BN1: D_56 | BO1: W_56 | BP1: D_57 | BQ1: W_57 | BR1: D_58 | BS1: W_58 | BT1: D_59 | BU1: W_59 | BV1: D_60 | BW1: W_60 | BX1: D_61 | BY1: W_61 | BZ1: D_62 | CA1: W_62 | CB1: D_64 | CC1: W_64 | CD1: D_65 | CE1: W_65 | CF1: D_66 | CG1: W_66 | CH1: D_67 | CI1: W_67 | CJ1: D_71 | CK1: W_71 | CL1: D_73 | CM1: W_73 | CN1: D_76 | CO1: W_76 | CP1: D_77 | CQ1: W_77 | CR1: D_78 | CS1: W_78 | CT1: D_79 | CU1: W_79 | CV1: D_80 | CW1: W_80 | CX1: D_81 | CY1: W_81 | CZ1: D_82 | DA1: W_82 | DB1: D_83 | DC1: W_83 | DD1: D_84 | DE1: W_84 | DF1: D_85 | DG1: W_85 | DH1: D_86 | DI1: W_86 | DJ1: D_87 | DK1: W_87 | DL1: D_88 | DM1: W_88 | DN1: D_89 | DO1: W_89 | DP1: D_90 | DQ1: W_90 | DR1: D_91 | DS1: W_91 | DT1: D_92 | DU1: W_92 | DV1: D_93 | DW1: W_93 | DX1: D_94 | DY1: W_94 | DZ1: D_95 | EA1: W_95 | EB1: D_96 | EC1: W_96 | ED1: D_97 | EE1: W_97 | EF1: D_98 | EG1: W_98 | EH1: D_99 | EI1: W_99 | EJ1: D_105 | EK1: W_105 | EL1: D_106 | EM1: W_106 | EN1: D_107 | EO1: W_107 | EP1: D_108 | EQ1: W_108 | ER1: D_109 | ES1: W_109 | ET1: D_110 | EU1: W_110 | EV1: D_111 | EW1: W_111 | EX1: D_112 | EY1: W_112 | EZ1: D_113 | FA1: W_113 | FB1: D_114 | FC1: W_114 | FD1: D_115 | FE1: W_115 | FF1: D_116 | FG1: W_116 | FH1: D_117 | FI1: W_117 | FJ1: D_118 | FK1: W_118 | FL1: D_119 | FM1: W_119 | FN1: D_120 | FO1: W_120 | FP1: D_121 | FQ1: W_121 | FR1: D_122 | FS1: W_122 | FT1: D_123 | FU1: W_123 | FV1: D_124 | FW1: W_124 | FX1: D_125 | FY1: W_125 | FZ1: D_126 | GA1: W_126 | GB1: D_139 | GC1: W_139 | GD1: D_140 | GE1: W_140 | GF1: D_141 | GG1: W_141 | GH1: D_142 | GI1: W_142 | GJ1: D_143 | GK1: W_143 | GL1: D_144 | GM1: W_144 | GN1: D_145 | GO1: W_145 | GP1: D_146 | GQ1: W_146 | GR1: D_147 | GS1: W_147 | GT1: D_148 | GU1: W_148 | GV1: D_149 | GW1: W_149 | GX1: D_150 | GY1: W_150 | GZ1: D_151 | HA1: W_151 | HB1: D_152 | HC1: W_152 | HD1: D_154 | HE1: W_154 | HF1: D_155 | HG1: W_155 | HH1: D_156 | HI1: W_156 | HJ1: D_157 | HK1: W_157 | HL1: D_158 | HM1: W_158 | HN1: D_159 | HO1: W_159 | HP1: D_160 | HQ1: W_160 | HR1: D_161 | HS1: W_161 | HT1: D_162 | HU1: W_162 | HV1: D_163 | HW1: W_163 | HX1: D_164 | HY1: W_164 | HZ1: D_165 | IA1: W_165 | IB1: D_166 | IC1: W_166 | ID1: D_167 | IE1: W_167 | IF1: D_168 | IG1: W_168 | IH1: D_169 | II1: W_169 | IJ1: D_170 | IK1: W_170 | IL1: D_171 | IM1: W_171 | IN1: D_173 | IO1: W_173 | IP1: D_174 | IQ1: W_174 | IR1: pocket_vol_mean | IS1: pocket_vol_std | IT1: pocket_vol_closed_frac | IU1: mean_n_hydrophobic | IV1: std_n_hydrophobic | IW1: occ_n_hydrophobic_gt0 | IX1: mean_n_polar | IY1: std_n_polar | IZ1: occ_n_polar_gt0 | JA1: mean_n_pos_charged | JB1: std_n_pos_charged | JC1: occ_n_pos_charged_gt0 | JD1: mean_n_neg_charged | JE1: std_n_neg_charged | JF1: occ_n_neg_charged_gt0 | JG1: mean_n_other | JH1: std_n_other | JI1: occ_n_other_gt0 | JJ1: mean_n_total | JK1: std_n_total | JL1: occ_n_total_gt0 | JM1: mean_frac_hydrophobic | JN1: std_frac_hydrophobic | JO1: Y23 RMSF (A) | JP1: R79 RMSF (A) | JQ1: I110 RMSF (A) | JR1: G163 RMSF (A)
A2: seq16_binder | B2: 16 | C2: binder | D2: =IF(C2="Binder", 1,0) -> 1 | F2: MPSELTPEERSELKNSIAEFHTYQLDPGQCSSLHAQRIHAPPDLVWSIVRRFDKPQTYVPFIKSCSVEQNFEMRVGCTREDILISGLPASTMTVRLDILDDERRVTGASVIGGEHRVRNLKTVTTVHRFEKENKIWTVVLKSYVVDMPEGNSEDDTRMILDTGVKLILQKLATVAEAMARN | G2: 0.3103 | H2: 0.0525 | I2: 0.3432 | J2: 0.0621 | K2: 0.6839 | L2: 0.0759 | M2: 0.431 | N2: 0.1315 | O2: 10.4943 | P2: 1.3151 | Q2: 21.27 | R2: 25.86 | S2: 52.87 | T2: =VLOOKUP(A2,R_scores!A:T,3,FALSE) -> -0.0222 | U2: =VLOOKUP($A2,R_scores!$A:$T,4,FALSE) -> 0.272 | V2: =VLOOKUP($A2,R_scores!$A:$T,5,FALSE) -> -0.0039 | W2: =VLOOKUP($A2,R_scores!$A:$T,6,FALSE) -> 0.5066 | X2: =VLOOKUP($A2,R_scores!$A:$T,7,FALSE) -> 0.0543 | Y2: =VLOOKUP($A2,R_scores!$A:$T,8,FALSE) -> -0.1277 | Z2: =VLOOKUP($A2,R_scores!$A:$T,9,FALSE) -> 0.1494 | AA2: =VLOOKUP($A2,R_scores!$A:$T,10,FALSE) -> 0.3916 | AB2: =VLOOKUP($A2,R_scores!$A:$T,11,FALSE) -> 0.0918 | AC2: =VLOOKUP($A2,R_scores!$A:$T,12,FALSE) -> -0.1026 | AD2: =VLOOKUP($A2,R_scores!$A:$T,13,FALSE) -> -0.3577 | AE2: =VLOOKUP($A2,R_scores!$A:$T,14,FALSE) -> -0.3348 | AF2: =VLOOKUP($A2,R_scores!$A:$T,15,FALSE) -> 0.1563 | AG2: =VLOOKUP($A2,R_scores!$A:$T,16,FALSE) -> 0.4592 | AH2: =VLOOKUP($A2,R_scores!$A:$T,17,FALSE) -> 0.1157 | AI2: =VLOOKUP($A2,R_scores!$A:$T,18,FALSE) -> 0.3938 | AJ2: =VLOOKUP($A2,R_scores!$A:$T,19,FALSE) -> 0.0864 | AK2: =VLOOKUP($A2,R_scores!$A:$T,20,FALSE) -> 0.0005 | AL2: =VLOOKUP($A2,DW_avgs_500ns!$A:$HH,COLUMN(C2),FALSE) -> 0 | AM2: =VLOOKUP($A2,DW_avgs_500ns!$A:$HH,COLUMN(D2),FALSE) -> 0 | AN2: =VLOOKUP($A2,DW_avgs_500ns!$A:$HH,COLUMN(E2),FALSE) -> 0 | AO2: =VLOOKUP($A2,DW_avgs_500ns!$A:$HH,COLUMN(F2),FALSE) -> 0 | AP2: =VLOOKUP($A2,DW_avgs_500ns!$A:$HH,COLUMN(G2),FALSE) -> 0 | AQ2: =VLOOKUP($A2,DW_avgs_500ns!$A:$HH,COLUMN(H2),FALSE) -> 0 | AR2: =VLOOKUP($A2,DW_avgs_500ns!$A:$HH,COLUMN(I2),FALSE) -> 0 | AS2: =VLOOKUP($A2,DW_avgs_500ns!$A:$HH,COLUMN(J2),FALSE) -> 0 | ... IQ2: =VLOOKUP($A2,DW_avgs_500ns!$A:$HH,COLUMN(HH2),FALSE) -> 0 | IR2: =VLOOKUP($A$2,pkt_vol!A:H,COLUMN(C2),FALSE) -> 928.5762558082661 | IS2: =VLOOKUP($A2,pkt_vol!A:H,COLUMN(D2),FALSE) -> 98.99996524810939 | IT2: =VLOOKUP($A2,pkt_vol!A:H,COLUMN(G2),FALSE) -> 0.084780305 | IU2: =VLOOKUP($A2,lig_contacts!$A:$U,COLUMN(B2),FALSE) -> 14.558816336512594 | IV2: =VLOOKUP($A2,lig_contacts!$A:$U,COLUMN(C2),FALSE) -> 2.068570861508442 | IW2: =VLOOKUP($A2,lig_contacts!$A:$U,COLUMN(D2),FALSE) -> 1 | IX2: =VLOOKUP($A2,lig_contacts!$A:$U,COLUMN(E2),FALSE) -> 2.1300236406619386 | IY2: =VLOOKUP($A2,lig_contacts!$A:$U,COLUMN(F2),FALSE) -> 0.8867388127919622 | IZ2: =VLOOKUP($A2,lig_contacts!$A:$U,COLUMN(G2),FALSE) -> 0.98769055 | JA2: =VLOOKUP($A2,lig_contacts!$A:$U,COLUMN(H2),FALSE) -> 2.668704654764816 | JB2: =VLOOKUP($A2,lig_contacts!$A:$U,COLUMN(I2),FALSE) -> 0.7013255170027929 | ... JN2: =VLOOKUP($A2,lig_contacts!$A:$U,COLUMN(U2),FALSE) -> 0.047587199 | JO2: 2.893 | JP2: 0.546 | JQ2: 0.6759999999999999 | JR2: 0.7589999999999999
A3: seq14_binder | B3: 14 | C3: binder | D3: =IF(C3="Binder", 1,0) -> 1 | F3: MPSELTPEERSELKNSIAEFHTYQLDPGQCSSLHAQRIHAPPDLVWSIVRRFDKPQTYVPFIKSCSVEQNFEMRVGCTREDILISGLPASTMTLRLDILDDERRVTGASVIGGEHRVRNLKTVTTVHRFEKENKIWTVVLKSYVVDMPEGNSEDDTRMIMDTGIKLILQKLATVAEAMARN | G3: 0.2811 | H3: 0.0542 | I3: 0.2676 | J3: 0.0383 | K3: 0.3398 | L3: 0.0543 | M3: 0.3379 | N3: 0.0544 | O3: 8.2758 | P3: 0.4521 | Q3: 97.72 | R3: 0.06 | S3: 2.23 | T3: =VLOOKUP(A3,R_scores!A:T,3,FALSE) -> -0.3403 | U3: =VLOOKUP($A3,R_scores!$A:$T,4,FALSE) -> 0.1198 | V3: =VLOOKUP($A3,R_scores!$A:$T,5,FALSE) -> 0.0067 | W3: =VLOOKUP($A3,R_scores!$A:$T,6,FALSE) -> 0.3319 | X3: =VLOOKUP($A3,R_scores!$A:$T,7,FALSE) -> 0.0323 | Y3: =VLOOKUP($A3,R_scores!$A:$T,8,FALSE) -> 0.5885 | Z3: =VLOOKUP($A3,R_scores!$A:$T,9,FALSE) -> 0.6125 | AA3: =VLOOKUP($A3,R_scores!$A:$T,10,FALSE) -> 0.1867 | AB3: =VLOOKUP($A3,R_scores!$A:$T,11,FALSE) -> 0.0001 | AC3: =VLOOKUP($A3,R_scores!$A:$T,12,FALSE) -> -0.0107 | AD3: =VLOOKUP($A3,R_scores!$A:$T,13,FALSE) -> 0.1361 | AE3: =VLOOKUP($A3,R_scores!$A:$T,14,FALSE) -> 0.3312 | AF3: =VLOOKUP($A3,R_scores!$A:$T,15,FALSE) -> 0.0956 | AG3: =VLOOKUP($A3,R_scores!$A:$T,16,FALSE) -> 0.1286 | AH3: =VLOOKUP($A3,R_scores!$A:$T,17,FALSE) -> 0.408 | AI3: =VLOOKUP($A3,R_scores!$A:$T,18,FALSE) -> 0.1174 | AJ3: =VLOOKUP($A3,R_scores!$A:$T,19,FALSE) -> -0.0175 | AK3: =VLOOKUP($A3,R_scores!$A:$T,20,FALSE) -> -0.3327 | AL3: =VLOOKUP($A3,DW_avgs_500ns!$A:$HH,COLUMN(C3),FALSE) -> 0 | AM3: =VLOOKUP($A3,DW_avgs_500ns!$A:$HH,COLUMN(D3),FALSE) -> 0 | AN3: =VLOOKUP($A3,DW_avgs_500ns!$A:$HH,COLUMN(E3),FALSE) -> 0 | AO3: =VLOOKUP($A3,DW_avgs_500ns!$A:$HH,COLUMN(F3),FALSE) -> 0 | AP3: =VLOOKUP($A3,DW_avgs_500ns!$A:$HH,COLUMN(G3),FALSE) -> 0 | AQ3: =VLOOKUP($A3,DW_avgs_500ns!$A:$HH,COLUMN(H3),FALSE) -> 0 | AR3: =VLOOKUP($A3,DW_avgs_500ns!$A:$HH,COLUMN(I3),FALSE) -> 0 | AS3: =VLOOKUP($A3,DW_avgs_500ns!$A:$HH,COLUMN(J3),FALSE) -> 0 | ... IQ3: =VLOOKUP($A3,DW_avgs_500ns!$A:$HH,COLUMN(HH3),FALSE) -> 0 | IR3: =VLOOKUP(A3,pkt_vol!A:H,COLUMN(C3),FALSE) -> 952.08445 | IS3: =VLOOKUP($A3,pkt_vol!A:H,COLUMN(D3),FALSE) -> 125.10616134195399 | IT3: =VLOOKUP($A3,pkt_vol!A:H,COLUMN(G3),FALSE) -> 0.11640988016629983 | IU3: =VLOOKUP($A3,lig_contacts!$A:$U,COLUMN(B3),FALSE) -> 14.63234694709383 | IV3: =VLOOKUP($A3,lig_contacts!$A:$U,COLUMN(C3),FALSE) -> 1.156248587347947 | IW3: =VLOOKUP($A3,lig_contacts!$A:$U,COLUMN(D3),FALSE) -> 1 | IX3: =VLOOKUP($A3,lig_contacts!$A:$U,COLUMN(E3),FALSE) -> 2.560202168419337 | IY3: =VLOOKUP($A3,lig_contacts!$A:$U,COLUMN(F3),FALSE) -> 0.5261786776998156 | IZ3: =VLOOKUP($A3,lig_contacts!$A:$U,COLUMN(G3),FALSE) -> 0.99991848 | JA3: =VLOOKUP($A3,lig_contacts!$A:$U,COLUMN(H3),FALSE) -> 2.550093747452515 | JB3: =VLOOKUP($A3,lig_contacts!$A:$U,COLUMN(I3),FALSE) -> 0.8496671381872838 | ... JN3: =VLOOKUP($A3,lig_contacts!$A:$U,COLUMN(U3),FALSE) -> 0.042101084 | JO3: 2.463 | JP3: 0.51 | JQ3: 0.684 | JR3: 0.62
A4: seq10_binder | B4: 10 | C4: binder | D4: =IF(C4="Binder", 1,0) -> 1 | F4: MPSELTPEERSELKNSIAEFHTYQLDPGQCSSLHAQRIHAPPDLVWSIVRRFDKPQTYVPFIKSCSVEQNFEMRVGCTREDILISGLPASTMTVRLDILDDERRVTGASVIGGEHRVRNLKTVTTVHRFEKENKIWTVVLKSYVVDMPEGNSEDDTRMIVDTGVKLLLQKLATVAEAMARN | G4: 1.0638 | H4: 0.4775 | I4: 0.2861 | J4: 0.0553 | K4: 0.3176 | L4: 0.055 | M4: 0.495 | N4: 0.1043 | O4: 9.9072 | P4: 0.6194 | Q4: 19.51 | R4: 1.1 | S4: 79.38 | T4: =VLOOKUP(A4,R_scores!A:T,3,FALSE) -> -0.3718 | U4: =VLOOKUP($A4,R_scores!$A:$T,4,FALSE) -> 0.2259 | V4: =VLOOKUP($A4,R_scores!$A:$T,5,FALSE) -> -0.1287 | W4: =VLOOKUP($A4,R_scores!$A:$T,6,FALSE) -> 0.1766 | X4: =VLOOKUP($A4,R_scores!$A:$T,7,FALSE) -> 0.0444 | Y4: =VLOOKUP($A4,R_scores!$A:$T,8,FALSE) -> -0.0419 | Z4: =VLOOKUP($A4,R_scores!$A:$T,9,FALSE) -> 0.0182 | AA4: =VLOOKUP($A4,R_scores!$A:$T,10,FALSE) -> 0.293 | AB4: =VLOOKUP($A4,R_scores!$A:$T,11,FALSE) -> 0.0223 | AC4: =VLOOKUP($A4,R_scores!$A:$T,12,FALSE) -> 0.2032 | AD4: =VLOOKUP($A4,R_scores!$A:$T,13,FALSE) -> -0.028 | AE4: =VLOOKUP($A4,R_scores!$A:$T,14,FALSE) -> -0.0086 | AF4: =VLOOKUP($A4,R_scores!$A:$T,15,FALSE) -> 0.3469 | AG4: =VLOOKUP($A4,R_scores!$A:$T,16,FALSE) -> 0.1539 | AH4: =VLOOKUP($A4,R_scores!$A:$T,17,FALSE) -> 0.1792 | AI4: =VLOOKUP($A4,R_scores!$A:$T,18,FALSE) -> 0.1637 | AJ4: =VLOOKUP($A4,R_scores!$A:$T,19,FALSE) -> 0.2561 | AK4: =VLOOKUP($A4,R_scores!$A:$T,20,FALSE) -> -0.1603 | AL4: =VLOOKUP($A4,DW_avgs_500ns!$A:$HH,COLUMN(C4),FALSE) -> 0 | AM4: =VLOOKUP($A4,DW_avgs_500ns!$A:$HH,COLUMN(D4),FALSE) -> 0 | AN4: =VLOOKUP($A4,DW_avgs_500ns!$A:$HH,COLUMN(E4),FALSE) -> 0 | AO4: =VLOOKUP($A4,DW_avgs_500ns!$A:$HH,COLUMN(F4),FALSE) -> 0 | AP4: =VLOOKUP($A4,DW_avgs_500ns!$A:$HH,COLUMN(G4),FALSE) -> 0 | AQ4: =VLOOKUP($A4,DW_avgs_500ns!$A:$HH,COLUMN(H4),FALSE) -> 0 | AR4: =VLOOKUP($A4,DW_avgs_500ns!$A:$HH,COLUMN(I4),FALSE) -> 0 | AS4: =VLOOKUP($A4,DW_avgs_500ns!$A:$HH,COLUMN(J4),FALSE) -> 0 | ... IQ4: =VLOOKUP($A4,DW_avgs_500ns!$A:$HH,COLUMN(HH4),FALSE) -> 0 | IR4: =VLOOKUP(A4,pkt_vol!A:H,COLUMN(C4),FALSE) -> 961.2702991766528 | IS4: =VLOOKUP($A4,pkt_vol!A:H,COLUMN(D4),FALSE) -> 107.61396370256874 | IT4: =VLOOKUP($A4,pkt_vol!A:H,COLUMN(G4),FALSE) -> 0.074427325 | IU4: =VLOOKUP($A4,lig_contacts!$A:$U,COLUMN(B4),FALSE) -> 13.707181870057878 | IV4: =VLOOKUP($A4,lig_contacts!$A:$U,COLUMN(C4),FALSE) -> 1.5486511795267746 | IW4: =VLOOKUP($A4,lig_contacts!$A:$U,COLUMN(D4),FALSE) -> 1 | IX4: =VLOOKUP($A4,lig_contacts!$A:$U,COLUMN(E4),FALSE) -> 2.231026330806228 | IY4: =VLOOKUP($A4,lig_contacts!$A:$U,COLUMN(F4),FALSE) -> 0.6562695845052414 | IZ4: =VLOOKUP($A4,lig_contacts!$A:$U,COLUMN(G4),FALSE) -> 0.9983696095214804 | JA4: =VLOOKUP($A4,lig_contacts!$A:$U,COLUMN(H4),FALSE) -> 2.171924675959892 | JB4: =VLOOKUP($A4,lig_contacts!$A:$U,COLUMN(I4),FALSE) -> 0.5315826962088444 | ... JN4: =VLOOKUP($A4,lig_contacts!$A:$U,COLUMN(U4),FALSE) -> 0.042988273 | JO4: 1.674 | JP4: 0.805 | JQ4: 0.871 | JR4: 1.0050000000000001
A5: seq17_binder | B5: 17 | C5: binder | D5: =IF(C5="Binder", 1,0) -> 1 | F5: MPSELTPEERSELKNSIAEFHTYQLDPGQCSSLHAQRIHAPPDLVWSIVRRFDKPQTYAPFIKSCSVEQNFEMRVGCTREDILISGLPASTMTVRLDILDDERRVTGVSIIGGEHRLRNYKSVTTVHRFEKENKIWTVVLKSYVVDMPEGNSEDDTRMILDTGVKLILQKLATVAEAMARN | G5: 0.2913 | H5: 0.0484 | I5: 0.3216 | J5: 0.0643 | K5: 0.9536 | L5: 0.255 | M5: 0.4221 | N5: 0.146 | O5: 8.5533 | P5: 0.7613 | Q5: 89.86 | R5: 0.47 | S5: 9.67 | T5: =VLOOKUP(A5,R_scores!A:T,3,FALSE) -> 0.3391 | U5: =VLOOKUP($A5,R_scores!$A:$T,4,FALSE) -> 0.1332 | V5: =VLOOKUP($A5,R_scores!$A:$T,5,FALSE) -> 0.192 | W5: =VLOOKUP($A5,R_scores!$A:$T,6,FALSE) -> 0.447 | X5: =VLOOKUP($A5,R_scores!$A:$T,7,FALSE) -> 0.0286 | Y5: =VLOOKUP($A5,R_scores!$A:$T,8,FALSE) -> 0.0361 | Z5: =VLOOKUP($A5,R_scores!$A:$T,9,FALSE) -> 0.0614 | AA5: =VLOOKUP($A5,R_scores!$A:$T,10,FALSE) -> 0.4611 | AB5: =VLOOKUP($A5,R_scores!$A:$T,11,FALSE) -> 0.1335 | AC5: =VLOOKUP($A5,R_scores!$A:$T,12,FALSE) -> 0.1425 | AD5: =VLOOKUP($A5,R_scores!$A:$T,13,FALSE) -> -0.0061 | AE5: =VLOOKUP($A5,R_scores!$A:$T,14,FALSE) -> -0.0896 | AF5: =VLOOKUP($A5,R_scores!$A:$T,15,FALSE) -> 0.365 | AG5: =VLOOKUP($A5,R_scores!$A:$T,16,FALSE) -> -0.0131 | AH5: =VLOOKUP($A5,R_scores!$A:$T,17,FALSE) -> 0.3492 | AI5: =VLOOKUP($A5,R_scores!$A:$T,18,FALSE) -> 0.251 | AJ5: =VLOOKUP($A5,R_scores!$A:$T,19,FALSE) -> 0.3882 | AK5: =VLOOKUP($A5,R_scores!$A:$T,20,FALSE) -> -0.0132 | AL5: =VLOOKUP($A5,DW_avgs_500ns!$A:$HH,COLUMN(C5),FALSE) -> 0 | AM5: =VLOOKUP($A5,DW_avgs_500ns!$A:$HH,COLUMN(D5),FALSE) -> 0 | AN5: =VLOOKUP($A5,DW_avgs_500ns!$A:$HH,COLUMN(E5),FALSE) -> 0 | AO5: =VLOOKUP($A5,DW_avgs_500ns!$A:$HH,COLUMN(F5),FALSE) -> 0 | AP5: =VLOOKUP($A5,DW_avgs_500ns!$A:$HH,COLUMN(G5),FALSE) -> 0 | AQ5: =VLOOKUP($A5,DW_avgs_500ns!$A:$HH,COLUMN(H5),FALSE) -> 0 | AR5: =VLOOKUP($A5,DW_avgs_500ns!$A:$HH,COLUMN(I5),FALSE) -> 0 | AS5: =VLOOKUP($A5,DW_avgs_500ns!$A:$HH,COLUMN(J5),FALSE) -> 0 | ... IQ5: =VLOOKUP($A5,DW_avgs_500ns!$A:$HH,COLUMN(HH5),FALSE) -> 0 | IR5: =VLOOKUP(A5,pkt_vol!A:H,COLUMN(C5),FALSE) -> 865.1019002201027 | IS5: =VLOOKUP($A5,pkt_vol!A:H,COLUMN(D5),FALSE) -> 65.95260943216009 | IT5: =VLOOKUP($A5,pkt_vol!A:H,COLUMN(G5),FALSE) -> 0.12961604304230864 | IU5: =VLOOKUP($A5,lig_contacts!$A:$U,COLUMN(B5),FALSE) -> 14.756501182033096 | IV5: =VLOOKUP($A5,lig_contacts!$A:$U,COLUMN(C5),FALSE) -> 1.276409896830775 | IW5: =VLOOKUP($A5,lig_contacts!$A:$U,COLUMN(D5),FALSE) -> 1 | IX5: =VLOOKUP($A5,lig_contacts!$A:$U,COLUMN(E5),FALSE) -> 2.463846091138828 | IY5: =VLOOKUP($A5,lig_contacts!$A:$U,COLUMN(F5),FALSE) -> 0.5471727686535741 | IZ5: =VLOOKUP($A5,lig_contacts!$A:$U,COLUMN(G5),FALSE) -> 1 | JA5: =VLOOKUP($A5,lig_contacts!$A:$U,COLUMN(H5),FALSE) -> 2.913018667970979 | JB5: =VLOOKUP($A5,lig_contacts!$A:$U,COLUMN(I5),FALSE) -> 0.4552342182035696 | ... JN5: =VLOOKUP($A5,lig_contacts!$A:$U,COLUMN(U5),FALSE) -> 0.032230444 | JO5: 1.387 | JP5: 0.573 | JQ5: 0.6819999999999999 | JR5: 0.598
A6: seq39_binder | B6: 39 | C6: binder | D6: =IF(C6="Binder", 1,0) -> 1 | F6: MPSELTPEERSELKNSIAEFHTYQLDPGQCSSLHAQRIHAPPDLVWSIVRRFDKPQTYVPFIKSCSVEQNFEMRVGCTREDILISGLPASTMTVRLDILDDERRVTGASVIGGEHRLRNYKSVTTVHRFEKENKIWTVVLKSYVVDMPEGNSEDDTRMIVDTGVKLLLQKLATVAEAMARN | G6: 0.366 | H6: 0.0559 | I6: 0.559 | J6: 0.1602 | K6: 0.6841 | L6: 0.1313 | M6: 0.6088 | N6: 0.1403 | O6: 9.4531 | P6: 1.3982 | Q6: 42.31 | R6: 6.34 | S6: 51.35 | T6: =VLOOKUP(A6,R_scores!A:T,3,FALSE) -> 0.0625 | U6: =VLOOKUP($A6,R_scores!$A:$T,4,FALSE) -> 0.0315 | V6: =VLOOKUP($A6,R_scores!$A:$T,5,FALSE) -> 0.1132 | W6: =VLOOKUP($A6,R_scores!$A:$T,6,FALSE) -> 0.3562 | X6: =VLOOKUP($A6,R_scores!$A:$T,7,FALSE) -> 0.0596 | Y6: =VLOOKUP($A6,R_scores!$A:$T,8,FALSE) -> 0.0165 | Z6: =VLOOKUP($A6,R_scores!$A:$T,9,FALSE) -> 0.0217 | AA6: =VLOOKUP($A6,R_scores!$A:$T,10,FALSE) -> 0.3104 | AB6: =VLOOKUP($A6,R_scores!$A:$T,11,FALSE) -> 0.001 | AC6: =VLOOKUP($A6,R_scores!$A:$T,12,FALSE) -> -0.0054 | AD6: =VLOOKUP($A6,R_scores!$A:$T,13,FALSE) -> -0.0528 | AE6: =VLOOKUP($A6,R_scores!$A:$T,14,FALSE) -> -0.0623 | AF6: =VLOOKUP($A6,R_scores!$A:$T,15,FALSE) -> 0.3178 | AG6: =VLOOKUP($A6,R_scores!$A:$T,16,FALSE) -> -0.0406 | AH6: =VLOOKUP($A6,R_scores!$A:$T,17,FALSE) -> 0.0335 | AI6: =VLOOKUP($A6,R_scores!$A:$T,18,FALSE) -> 0.0994 | AJ6: =VLOOKUP($A6,R_scores!$A:$T,19,FALSE) -> 0.2128 | AK6: =VLOOKUP($A6,R_scores!$A:$T,20,FALSE) -> -0.0306 | AL6: =VLOOKUP($A6,DW_avgs_500ns!$A:$HH,COLUMN(C6),FALSE) -> 0 | AM6: =VLOOKUP($A6,DW_avgs_500ns!$A:$HH,COLUMN(D6),FALSE) -> 0 | AN6: =VLOOKUP($A6,DW_avgs_500ns!$A:$HH,COLUMN(E6),FALSE) -> 0 | AO6: =VLOOKUP($A6,DW_avgs_500ns!$A:$HH,COLUMN(F6),FALSE) -> 0 | AP6: =VLOOKUP($A6,DW_avgs_500ns!$A:$HH,COLUMN(G6),FALSE) -> 0 | AQ6: =VLOOKUP($A6,DW_avgs_500ns!$A:$HH,COLUMN(H6),FALSE) -> 0 | AR6: =VLOOKUP($A6,DW_avgs_500ns!$A:$HH,COLUMN(I6),FALSE) -> 0 | AS6: =VLOOKUP($A6,DW_avgs_500ns!$A:$HH,COLUMN(J6),FALSE) -> 0 | ... IQ6: =VLOOKUP($A6,DW_avgs_500ns!$A:$HH,COLUMN(HH6),FALSE) -> 0 | IR6: =VLOOKUP(A6,pkt_vol!A:H,COLUMN(C6),FALSE) -> 971.0259223934133 | IS6: =VLOOKUP($A6,pkt_vol!A:H,COLUMN(D6),FALSE) -> 101.60480258358403 | IT6: =VLOOKUP($A6,pkt_vol!A:H,COLUMN(G6),FALSE) -> 0.055514795793592565 | IU6: =VLOOKUP($A6,lig_contacts!$A:$U,COLUMN(B6),FALSE) -> 12.742479823917828 | IV6: =VLOOKUP($A6,lig_contacts!$A:$U,COLUMN(C6),FALSE) -> 1.7518112711076734 | IW6: =VLOOKUP($A6,lig_contacts!$A:$U,COLUMN(D6),FALSE) -> 1 | IX6: =VLOOKUP($A6,lig_contacts!$A:$U,COLUMN(E6),FALSE) -> 2.315072959973914 | IY6: =VLOOKUP($A6,lig_contacts!$A:$U,COLUMN(F6),FALSE) -> 1.1589020522527542 | IZ6: =VLOOKUP($A6,lig_contacts!$A:$U,COLUMN(G6),FALSE) -> 0.9990217657128884 | JA6: =VLOOKUP($A6,lig_contacts!$A:$U,COLUMN(H6),FALSE) -> 1.9024211298606013 | JB6: =VLOOKUP($A6,lig_contacts!$A:$U,COLUMN(I6),FALSE) -> 0.5053071316910422 | ... JN6: =VLOOKUP($A6,lig_contacts!$A:$U,COLUMN(U6),FALSE) -> 0.048055346 | JO6: 2.16 | JP6: 0.663 | JQ6: 0.671 | JR6: 1.319
A7: seq42_binder | B7: 42 | C7: binder | D7: =IF(C7="Binder", 1,0) -> 1 | F7: MPSELTPEERSELKNSIAEFHTYQLDPGQCSSLHAQRIHAPPDLVWSIVRRFDKPQTYLPFIKSCSVEQNFEMRVGCTRELIVISGLPASTATVRLDILDDERRVTGGSVIGGEHRLRNLKWVTTVHRFEKENKIWTVVLQSYVVDMPEGNSEDDTRMYVDTFIKLVLQKLATVAEAMARN | G7: 0.305 | H7: 0.0549 | I7: 0.8116 | J7: 0.4074 | K7: 0.5456 | L7: 0.1087 | M7: 0.33 | N7: 0.0579 | O7: 11.0828 | P7: 1.4093 | Q7: 14.74 | R7: 43.21 | S7: 42.05 | T7: =VLOOKUP(A7,R_scores!A:T,3,FALSE) -> -0.3804 | U7: =VLOOKUP($A7,R_scores!$A:$T,4,FALSE) -> 0.1533 | V7: =VLOOKUP($A7,R_scores!$A:$T,5,FALSE) -> 0.0098 | W7: =VLOOKUP($A7,R_scores!$A:$T,6,FALSE) -> 0.4741 | X7: =VLOOKUP($A7,R_scores!$A:$T,7,FALSE) -> 0.0362 | Y7: =VLOOKUP($A7,R_scores!$A:$T,8,FALSE) -> -0.0929 | Z7: =VLOOKUP($A7,R_scores!$A:$T,9,FALSE) -> 0.1102 | AA7: =VLOOKUP($A7,R_scores!$A:$T,10,FALSE) -> 0.2696 | AB7: =VLOOKUP($A7,R_scores!$A:$T,11,FALSE) -> 0.011 | AC7: =VLOOKUP($A7,R_scores!$A:$T,12,FALSE) -> -0.3129 | AD7: =VLOOKUP($A7,R_scores!$A:$T,13,FALSE) -> -0.1252 | AE7: =VLOOKUP($A7,R_scores!$A:$T,14,FALSE) -> -0.0625 | AF7: =VLOOKUP($A7,R_scores!$A:$T,15,FALSE) -> 0.0704 | AG7: =VLOOKUP($A7,R_scores!$A:$T,16,FALSE) -> 0.1374 | AH7: =VLOOKUP($A7,R_scores!$A:$T,17,FALSE) -> -0.2337 | AI7: =VLOOKUP($A7,R_scores!$A:$T,18,FALSE) -> 0.0006 | AJ7: =VLOOKUP($A7,R_scores!$A:$T,19,FALSE) -> 0.6747 | AK7: =VLOOKUP($A7,R_scores!$A:$T,20,FALSE) -> 0.337 | AL7: =VLOOKUP($A7,DW_avgs_500ns!$A:$HH,COLUMN(C7),FALSE) -> 0 | AM7: =VLOOKUP($A7,DW_avgs_500ns!$A:$HH,COLUMN(D7),FALSE) -> 0 | AN7: =VLOOKUP($A7,DW_avgs_500ns!$A:$HH,COLUMN(E7),FALSE) -> 0 | AO7: =VLOOKUP($A7,DW_avgs_500ns!$A:$HH,COLUMN(F7),FALSE) -> 0 | AP7: =VLOOKUP($A7,DW_avgs_500ns!$A:$HH,COLUMN(G7),FALSE) -> 0 | AQ7: =VLOOKUP($A7,DW_avgs_500ns!$A:$HH,COLUMN(H7),FALSE) -> 0 | AR7: =VLOOKUP($A7,DW_avgs_500ns!$A:$HH,COLUMN(I7),FALSE) -> 0 | AS7: =VLOOKUP($A7,DW_avgs_500ns!$A:$HH,COLUMN(J7),FALSE) -> 0 | ... IQ7: =VLOOKUP($A7,DW_avgs_500ns!$A:$HH,COLUMN(HH7),FALSE) -> 0 | IR7: =VLOOKUP(A7,pkt_vol!A:H,COLUMN(C7),FALSE) -> 1012.2180794000163 | IS7: =VLOOKUP($A7,pkt_vol!A:H,COLUMN(D7),FALSE) -> 117.70170566245643 | IT7: =VLOOKUP($A7,pkt_vol!A:H,COLUMN(G7),FALSE) -> 0.044346621 | IU7: =VLOOKUP($A7,lig_contacts!$A:$U,COLUMN(B7),FALSE) -> 13.425205836797913 | IV7: =VLOOKUP($A7,lig_contacts!$A:$U,COLUMN(C7),FALSE) -> 1.3994993327138148 | IW7: =VLOOKUP($A7,lig_contacts!$A:$U,COLUMN(D7),FALSE) -> 1 | IX7: =VLOOKUP($A7,lig_contacts!$A:$U,COLUMN(E7),FALSE) -> 2.4099616858237547 | IY7: =VLOOKUP($A7,lig_contacts!$A:$U,COLUMN(F7),FALSE) -> 0.9048343789227596 | IZ7: =VLOOKUP($A7,lig_contacts!$A:$U,COLUMN(G7),FALSE) -> 0.9902176571288824 | JA7: =VLOOKUP($A7,lig_contacts!$A:$U,COLUMN(H7),FALSE) -> 0.9267139479905436 | JB7: =VLOOKUP($A7,lig_contacts!$A:$U,COLUMN(I7),FALSE) -> 0.5279438374135155 | ... JN7: =VLOOKUP($A7,lig_contacts!$A:$U,COLUMN(U7),FALSE) -> 0.057225076 | JO7: 2.926 | JP7: 1.6280000000000001 | JQ7: 0.9470000000000001 | JR7: 1.0150000000000001
A8: pair_3069_binder | B8: 3069 | C8: binder | D8: =IF(C8="Binder", 1,0) -> 1 | E8: 0.7232 | F8: MASELTPEERSELKNSIAEFHTYQLDPGSCSSLHAQRIHAPPELVWSIVRRFDKPQTYAHFIKSCSVEQNFEMRVGCTRDDILISGLPANTMTVRLDILDDERRVTGVSIIGGEHRLTNYKSVTTVHRFEKENRIWTVVLKSYVVDMPEGNSEDDTRMILDTGVKLILQKLATVAEAMARN | G8: 0.3704 | H8: 0.088 | I8: 0.317 | J8: 0.0346 | K8: 1.0124 | L8: 0.3012 | M8: 0.5213 | N8: 0.1372 | O8: 9.7301 | P8: 0.812 | Q8: 36.37 | R8: 2.86 | S8: 60.77 | T8: =VLOOKUP(A8,R_scores!A:T,3,FALSE) -> -0.1168 | U8: =VLOOKUP($A8,R_scores!$A:$T,4,FALSE) -> -0.0136 | V8: =VLOOKUP($A8,R_scores!$A:$T,5,FALSE) -> 0.0826 | W8: =VLOOKUP($A8,R_scores!$A:$T,6,FALSE) -> 0.3023 | X8: =VLOOKUP($A8,R_scores!$A:$T,7,FALSE) -> 0.0265 | Y8: =VLOOKUP($A8,R_scores!$A:$T,8,FALSE) -> 0.0856 | Z8: =VLOOKUP($A8,R_scores!$A:$T,9,FALSE) -> 0.0234 | AA8: =VLOOKUP($A8,R_scores!$A:$T,10,FALSE) -> -0.0584 | AB8: =VLOOKUP($A8,R_scores!$A:$T,11,FALSE) -> -0.1352 | AC8: =VLOOKUP($A8,R_scores!$A:$T,12,FALSE) -> -0.1598 | AD8: =VLOOKUP($A8,R_scores!$A:$T,13,FALSE) -> 0 | AE8: =VLOOKUP($A8,R_scores!$A:$T,14,FALSE) -> 0.11 | AF8: =VLOOKUP($A8,R_scores!$A:$T,15,FALSE) -> 0.0345 | AG8: =VLOOKUP($A8,R_scores!$A:$T,16,FALSE) -> -0.3101 | AH8: =VLOOKUP($A8,R_scores!$A:$T,17,FALSE) -> 0.1274 | AI8: =VLOOKUP($A8,R_scores!$A:$T,18,FALSE) -> 0.2262 | AJ8: =VLOOKUP($A8,R_scores!$A:$T,19,FALSE) -> -0.0425 | AK8: =VLOOKUP($A8,R_scores!$A:$T,20,FALSE) -> -0.2415 | AL8: =VLOOKUP($A8,DW_avgs_500ns!$A:$HH,COLUMN(C8),FALSE) -> 0 | AM8: =VLOOKUP($A8,DW_avgs_500ns!$A:$HH,COLUMN(D8),FALSE) -> 0 | AN8: =VLOOKUP($A8,DW_avgs_500ns!$A:$HH,COLUMN(E8),FALSE) -> 0 | AO8: =VLOOKUP($A8,DW_avgs_500ns!$A:$HH,COLUMN(F8),FALSE) -> 0 | AP8: =VLOOKUP($A8,DW_avgs_500ns!$A:$HH,COLUMN(G8),FALSE) -> 0 | AQ8: =VLOOKUP($A8,DW_avgs_500ns!$A:$HH,COLUMN(H8),FALSE) -> 0 | AR8: =VLOOKUP($A8,DW_avgs_500ns!$A:$HH,COLUMN(I8),FALSE) -> 0 | AS8: =VLOOKUP($A8,DW_avgs_500ns!$A:$HH,COLUMN(J8),FALSE) -> 0 | ... IQ8: =VLOOKUP($A8,DW_avgs_500ns!$A:$HH,COLUMN(HH8),FALSE) -> 0 | IR8: =VLOOKUP(A8,pkt_vol!A:H,COLUMN(C8),FALSE) -> 1055.0946849270401 | IS8: =VLOOKUP($A8,pkt_vol!A:H,COLUMN(D8),FALSE) -> 135.28990039989142 | IT8: =VLOOKUP($A8,pkt_vol!A:H,COLUMN(G8),FALSE) -> 0.035216434 | IU8: =VLOOKUP($A8,lig_contacts!$A:$U,COLUMN(B8),FALSE) -> 14.04662916768566 | IV8: =VLOOKUP($A8,lig_contacts!$A:$U,COLUMN(C8),FALSE) -> 1.6584372 | IW8: =VLOOKUP($A8,lig_contacts!$A:$U,COLUMN(D8),FALSE) -> 1 | IX8: =VLOOKUP($A8,lig_contacts!$A:$U,COLUMN(E8),FALSE) -> 1.7655498491888808 | IY8: =VLOOKUP($A8,lig_contacts!$A:$U,COLUMN(F8),FALSE) -> 0.6508092902149966 | IZ8: =VLOOKUP($A8,lig_contacts!$A:$U,COLUMN(G8),FALSE) -> 0.99975544 | JA8: =VLOOKUP($A8,lig_contacts!$A:$U,COLUMN(H8),FALSE) -> 2.542675470775251 | JB8: =VLOOKUP($A8,lig_contacts!$A:$U,COLUMN(I8),FALSE) -> 0.9274844418265842 | ... JN8: =VLOOKUP($A8,lig_contacts!$A:$U,COLUMN(U8),FALSE) -> 0.056986357 | JO8: 1.196 | JP8: 0.7889999999999999 | JQ8: 0.7829999999999999 | JR8: 1.1300000000000001
A9: pair_3070_binder | B9: 3070 | C9: binder | D9: =IF(C9="Binder", 1,0) -> 1 | E9: 0.6667 | F9: MASELTPEERSELKNSIAEFHTYQLDPGSCSSLHAQRIHAPPELVWSIVRRFDKPQTYAHFIKSCSVEQNFEMRVGCTRDDILISGLPANTMTVRLDILDDERRVTGASVIGGEHRLTNYKSVTTVHRFEKENRIWTVVLKSYVVDMPEGNSEDDTRMIVDTGVKLLLQKLATVAEAMARN | G9: 0.3183 | H9: 0.0494 | I9: 0.4026 | J9: 0.1146 | K9: 0.8512 | L9: 0.1254 | M9: 0.4995 | N9: 0.1552 | O9: 8.4291 | P9: 1.1467 | Q9: 81.11 | R9: 0.14 | S9: 18.75 | T9: =VLOOKUP(A9,R_scores!A:T,3,FALSE) -> -0.2165 | U9: =VLOOKUP($A9,R_scores!$A:$T,4,FALSE) -> -0.0825 | V9: =VLOOKUP($A9,R_scores!$A:$T,5,FALSE) -> 0.0721 | W9: =VLOOKUP($A9,R_scores!$A:$T,6,FALSE) -> 0.4049 | X9: =VLOOKUP($A9,R_scores!$A:$T,7,FALSE) -> 0.1176 | Y9: =VLOOKUP($A9,R_scores!$A:$T,8,FALSE) -> 0.018 | Z9: =VLOOKUP($A9,R_scores!$A:$T,9,FALSE) -> -0.098 | AA9: =VLOOKUP($A9,R_scores!$A:$T,10,FALSE) -> -0.1718 | AB9: =VLOOKUP($A9,R_scores!$A:$T,11,FALSE) -> -0.0454 | AC9: =VLOOKUP($A9,R_scores!$A:$T,12,FALSE) -> -0.2714 | AD9: =VLOOKUP($A9,R_scores!$A:$T,13,FALSE) -> -0.2985 | AE9: =VLOOKUP($A9,R_scores!$A:$T,14,FALSE) -> -0.1216 | AF9: =VLOOKUP($A9,R_scores!$A:$T,15,FALSE) -> 0.4525 | AG9: =VLOOKUP($A9,R_scores!$A:$T,16,FALSE) -> 0.0827 | AH9: =VLOOKUP($A9,R_scores!$A:$T,17,FALSE) -> 0.0124 | AI9: =VLOOKUP($A9,R_scores!$A:$T,18,FALSE) -> 0.1328 | AJ9: =VLOOKUP($A9,R_scores!$A:$T,19,FALSE) -> 0.1434 | AK9: =VLOOKUP($A9,R_scores!$A:$T,20,FALSE) -> 0.2017 | AL9: =VLOOKUP($A9,DW_avgs_500ns!$A:$HH,COLUMN(C9),FALSE) -> 0 | AM9: =VLOOKUP($A9,DW_avgs_500ns!$A:$HH,COLUMN(D9),FALSE) -> 0 | AN9: =VLOOKUP($A9,DW_avgs_500ns!$A:$HH,COLUMN(E9),FALSE) -> 0 | AO9: =VLOOKUP($A9,DW_avgs_500ns!$A:$HH,COLUMN(F9),FALSE) -> 0 | AP9: =VLOOKUP($A9,DW_avgs_500ns!$A:$HH,COLUMN(G9),FALSE) -> 0 | AQ9: =VLOOKUP($A9,DW_avgs_500ns!$A:$HH,COLUMN(H9),FALSE) -> 0 | AR9: =VLOOKUP($A9,DW_avgs_500ns!$A:$HH,COLUMN(I9),FALSE) -> 0 | AS9: =VLOOKUP($A9,DW_avgs_500ns!$A:$HH,COLUMN(J9),FALSE) -> 0 | ... IQ9: =VLOOKUP($A9,DW_avgs_500ns!$A:$HH,COLUMN(HH9),FALSE) -> 0 | IR9: =VLOOKUP(A9,pkt_vol!A:H,COLUMN(C9),FALSE) -> 1027.096687861743 | IS9: =VLOOKUP($A9,pkt_vol!A:H,COLUMN(D9),FALSE) -> 128.75349590191342 | IT9: =VLOOKUP($A9,pkt_vol!A:H,COLUMN(G9),FALSE) -> 0.045650933398548955 | IU9: =VLOOKUP($A9,lig_contacts!$A:$U,COLUMN(B9),FALSE) -> 13.302355914241462 | IV9: =VLOOKUP($A9,lig_contacts!$A:$U,COLUMN(C9),FALSE) -> 1.6899465342628528 | IW9: =VLOOKUP($A9,lig_contacts!$A:$U,COLUMN(D9),FALSE) -> 1 | IX9: =VLOOKUP($A9,lig_contacts!$A:$U,COLUMN(E9),FALSE) -> 2.494905029754626 | IY9: =VLOOKUP($A9,lig_contacts!$A:$U,COLUMN(F9),FALSE) -> 1.3500550717871511 | IZ9: =VLOOKUP($A9,lig_contacts!$A:$U,COLUMN(G9),FALSE) -> 0.99983696 | JA9: =VLOOKUP($A9,lig_contacts!$A:$U,COLUMN(H9),FALSE) -> 1.8649221488546508 | JB9: =VLOOKUP($A9,lig_contacts!$A:$U,COLUMN(I9),FALSE) -> 0.6351806604416186 | ... JN9: =VLOOKUP($A9,lig_contacts!$A:$U,COLUMN(U9),FALSE) -> 0.058283435 | JO9: 1.5379999999999998 | JP9: 0.718 | JQ9: 0.665 | JR9: 0.637
A10: pair_3074_binder | B10: 3074 | C10: binder | D10: =IF(C10="Binder", 1,0) -> 1 | E10: 0.7 | F10: MASELTPEERSELKNSIAEFHTYQLDPGSCSSLHAQRIHAPPELVWSIVRRFDKPQTYAHFIKSCSVEQNFEMRVGCTRDDILISGLPANTMTVRLDILDDERRVTGVSIIGGEHRLTNYKSVTTVHRFEKENRIWTVVLKSYVVDMPEGNSEDDTRMHVDTLTKLALQKLATVAEAMARN | G10: 0.3319 | H10: 0.0667 | I10: 0.3328 | J10: 0.0654 | K10: 1.2924 | L10: 0.2609 | M10: 0.3241 | N10: 0.0639 | O10: 10.6187 | P10: 0.8137 | Q10: 3.77 | R10: 13.42 | S10: 82.81 | T10: =VLOOKUP(A10,R_scores!A:T,3,FALSE) -> -0.0208 | U10: =VLOOKUP($A10,R_scores!$A:$T,4,FALSE) -> -0.0189 | V10: =VLOOKUP($A10,R_scores!$A:$T,5,FALSE) -> -0.0675 | W10: =VLOOKUP($A10,R_scores!$A:$T,6,FALSE) -> 0.3637 | X10: =VLOOKUP($A10,R_scores!$A:$T,7,FALSE) -> 0.0123 | Y10: =VLOOKUP($A10,R_scores!$A:$T,8,FALSE) -> -0.0781 | Z10: =VLOOKUP($A10,R_scores!$A:$T,9,FALSE) -> 0.0493 | AA10: =VLOOKUP($A10,R_scores!$A:$T,10,FALSE) -> 0.2201 | AB10: =VLOOKUP($A10,R_scores!$A:$T,11,FALSE) -> 0.117 | AC10: =VLOOKUP($A10,R_scores!$A:$T,12,FALSE) -> 0.0743 | AD10: =VLOOKUP($A10,R_scores!$A:$T,13,FALSE) -> -0.1863 | AE10: =VLOOKUP($A10,R_scores!$A:$T,14,FALSE) -> 0.1977 | AF10: =VLOOKUP($A10,R_scores!$A:$T,15,FALSE) -> 0.1424 | AG10: =VLOOKUP($A10,R_scores!$A:$T,16,FALSE) -> -0.1999 | AH10: =VLOOKUP($A10,R_scores!$A:$T,17,FALSE) -> 0.0112 | AI10: =VLOOKUP($A10,R_scores!$A:$T,18,FALSE) -> 0.074 | AJ10: =VLOOKUP($A10,R_scores!$A:$T,19,FALSE) -> 0.3102 | AK10: =VLOOKUP($A10,R_scores!$A:$T,20,FALSE) -> -0.178 | AL10: =VLOOKUP($A10,DW_avgs_500ns!$A:$HH,COLUMN(C10),FALSE) -> 0 | AM10: =VLOOKUP($A10,DW_avgs_500ns!$A:$HH,COLUMN(D10),FALSE) -> 0 | AN10: =VLOOKUP($A10,DW_avgs_500ns!$A:$HH,COLUMN(E10),FALSE) -> 0 | AO10: =VLOOKUP($A10,DW_avgs_500ns!$A:$HH,COLUMN(F10),FALSE) -> 0 | AP10: =VLOOKUP($A10,DW_avgs_500ns!$A:$HH,COLUMN(G10),FALSE) -> 0 | AQ10: =VLOOKUP($A10,DW_avgs_500ns!$A:$HH,COLUMN(H10),FALSE) -> 0 | AR10: =VLOOKUP($A10,DW_avgs_500ns!$A:$HH,COLUMN(I10),FALSE) -> 0 | AS10: =VLOOKUP($A10,DW_avgs_500ns!$A:$HH,COLUMN(J10),FALSE) -> 0 | ... IQ10: =VLOOKUP($A10,DW_avgs_500ns!$A:$HH,COLUMN(HH10),FALSE) -> 0 | IR10: =VLOOKUP(A10,pkt_vol!A:H,COLUMN(C10),FALSE) -> 986.3516091954024 | IS10: =VLOOKUP($A10,pkt_vol!A:H,COLUMN(D10),FALSE) -> 129.73078778139202 | IT10: =VLOOKUP($A10,pkt_vol!A:H,COLUMN(G10),FALSE) -> 0.081682563 | IU10: =VLOOKUP($A10,lig_contacts!$A:$U,COLUMN(B10),FALSE) -> 11.065378658188637 | IV10: =VLOOKUP($A10,lig_contacts!$A:$U,COLUMN(C10),FALSE) -> 1.4932681285585885 | IW10: =VLOOKUP($A10,lig_contacts!$A:$U,COLUMN(D10),FALSE) -> 1 | IX10: =VLOOKUP($A10,lig_contacts!$A:$U,COLUMN(E10),FALSE) -> 2.7791636 | IY10: =VLOOKUP($A10,lig_contacts!$A:$U,COLUMN(F10),FALSE) -> 0.9293434887144396 | IZ10: =VLOOKUP($A10,lig_contacts!$A:$U,COLUMN(G10),FALSE) -> 0.9975544142822206 | JA10: =VLOOKUP($A10,lig_contacts!$A:$U,COLUMN(H10),FALSE) -> 3.2813238770685578 | JB10: =VLOOKUP($A10,lig_contacts!$A:$U,COLUMN(I10),FALSE) -> 0.7311753359009182 | ... JN10: =VLOOKUP($A10,lig_contacts!$A:$U,COLUMN(U10),FALSE) -> 0.047968878 | JO10: 2.838 | JP10: 0.7030000000000001 | JQ10: 0.605 | JR10: 0.671
A11: pair_3092_binder | B11: 3092 | C11: binder | D11: =IF(C11="Binder", 1,0) -> 1 | E11: 0.5769 | F11: MASELTPEERSELKNSIAEFHTYQLDPGSCSSLHAQRIHAPPELVWSIVRRFDKPQTYVHFIKSCSVEQNFEMRVGCTRDDILISGLPANTMTVRLDILDDERRVTGASVIGGEHRLTNYKSVTTVHRFEKENRIWTVVLKSYVVDMPEGNSEDDTRMIVDTGVKLLLQKLATVAEAMARN | G11: 0.3337 | H11: 0.0508 | I11: 0.389 | J11: 0.0642 | K11: 0.8609 | L11: 0.1351 | M11: 0.5792 | N11: 0.2063 | O11: 8.6023 | P11: 0.9759 | Q11: 86.28 | R11: 2.37 | S11: 11.35 | T11: =VLOOKUP(A11,R_scores!A:T,3,FALSE) -> -0.0699 | U11: =VLOOKUP($A11,R_scores!$A:$T,4,FALSE) -> -0.0922 | V11: =VLOOKUP($A11,R_scores!$A:$T,5,FALSE) -> -0.1044 | W11: =VLOOKUP($A11,R_scores!$A:$T,6,FALSE) -> 0.198 | X11: =VLOOKUP($A11,R_scores!$A:$T,7,FALSE) -> 0.1346 | Y11: =VLOOKUP($A11,R_scores!$A:$T,8,FALSE) -> 0.0733 | Z11: =VLOOKUP($A11,R_scores!$A:$T,9,FALSE) -> 0.0827 | AA11: =VLOOKUP($A11,R_scores!$A:$T,10,FALSE) -> -0.1588 | AB11: =VLOOKUP($A11,R_scores!$A:$T,11,FALSE) -> -0.108 | AC11: =VLOOKUP($A11,R_scores!$A:$T,12,FALSE) -> -0.1061 | AD11: =VLOOKUP($A11,R_scores!$A:$T,13,FALSE) -> -0.3026 | AE11: =VLOOKUP($A11,R_scores!$A:$T,14,FALSE) -> -0.1279 | AF11: =VLOOKUP($A11,R_scores!$A:$T,15,FALSE) -> 0.5726 | AG11: =VLOOKUP($A11,R_scores!$A:$T,16,FALSE) -> 0.3283 | AH11: =VLOOKUP($A11,R_scores!$A:$T,17,FALSE) -> 0.1571 | AI11: =VLOOKUP($A11,R_scores!$A:$T,18,FALSE) -> 0.2423 | AJ11: =VLOOKUP($A11,R_scores!$A:$T,19,FALSE) -> -0.035 | AK11: =VLOOKUP($A11,R_scores!$A:$T,20,FALSE) -> 0.0329 | AL11: =VLOOKUP($A11,DW_avgs_500ns!$A:$HH,COLUMN(C11),FALSE) -> 0 | AM11: =VLOOKUP($A11,DW_avgs_500ns!$A:$HH,COLUMN(D11),FALSE) -> 0 | AN11: =VLOOKUP($A11,DW_avgs_500ns!$A:$HH,COLUMN(E11),FALSE) -> 0 | AO11: =VLOOKUP($A11,DW_avgs_500ns!$A:$HH,COLUMN(F11),FALSE) -> 0 | AP11: =VLOOKUP($A11,DW_avgs_500ns!$A:$HH,COLUMN(G11),FALSE) -> 0 | AQ11: =VLOOKUP($A11,DW_avgs_500ns!$A:$HH,COLUMN(H11),FALSE) -> 0 | AR11: =VLOOKUP($A11,DW_avgs_500ns!$A:$HH,COLUMN(I11),FALSE) -> 0 | AS11: =VLOOKUP($A11,DW_avgs_500ns!$A:$HH,COLUMN(J11),FALSE) -> 0 | ... IQ11: =VLOOKUP($A11,DW_avgs_500ns!$A:$HH,COLUMN(HH11),FALSE) -> 0 | IR11: =VLOOKUP(A11,pkt_vol!A:H,COLUMN(C11),FALSE) -> 973.3735412081194 | IS11: =VLOOKUP($A11,pkt_vol!A:H,COLUMN(D11),FALSE) -> 102.87067409621032 | IT11: =VLOOKUP($A11,pkt_vol!A:H,COLUMN(G11),FALSE) -> 0.059753811 | IU11: =VLOOKUP($A11,lig_contacts!$A:$U,COLUMN(B11),FALSE) -> 13.813890926876986 | IV11: =VLOOKUP($A11,lig_contacts!$A:$U,COLUMN(C11),FALSE) -> 1.3095243090056614 | IW11: =VLOOKUP($A11,lig_contacts!$A:$U,COLUMN(D11),FALSE) -> 1 | IX11: =VLOOKUP($A11,lig_contacts!$A:$U,COLUMN(E11),FALSE) -> 2.802396674003424 | IY11: =VLOOKUP($A11,lig_contacts!$A:$U,COLUMN(F11),FALSE) -> 0.7762161933717664 | IZ11: =VLOOKUP($A11,lig_contacts!$A:$U,COLUMN(G11),FALSE) -> 1 | JA11: =VLOOKUP($A11,lig_contacts!$A:$U,COLUMN(H11),FALSE) -> 1.5554740360316297 | JB11: =VLOOKUP($A11,lig_contacts!$A:$U,COLUMN(I11),FALSE) -> 0.6104307800399837 | ... JN11: =VLOOKUP($A11,lig_contacts!$A:$U,COLUMN(U11),FALSE) -> 0.040339681 | JO11: 2.838 | JP11: 0.7030000000000001 | JQ11: 0.605 | JR11: 0.671
A12: pair_3098_binder | B12: 3098 | C12: binder | D12: =IF(C12="Binder", 1,0) -> 1 | E12: 0.3871 | F12: MASELTPEERSELKNSIAEFHTYQLDPGSCSSLHAQRIHAPPELVWSIVRRFDKPQTYAHFIKSCSVEQNFEMRVGCTRDLILISGLPANTMTVRLDILDDERRVTGVSIIGGEHRLTNYKSVTTVHRFEKENRIWTVVLKSYVVDMPEGNSEDDTRMIVDTGVKLLLQKLATVAEAMARN | G12: 0.3536 | H12: 0.0634 | I12: 0.4556 | J12: 0.0841 | K12: 0.6164 | L12: 0.1304 | M12: 0.7672 | N12: 0.3667 | O12: 9.1345 | P12: 1.4009 | Q12: 59.52 | R12: 5.76 | S12: 34.72 | T12: =VLOOKUP(A12,R_scores!A:T,3,FALSE) -> -0.2829 | U12: =VLOOKUP($A12,R_scores!$A:$T,4,FALSE) -> -0.0091 | V12: =VLOOKUP($A12,R_scores!$A:$T,5,FALSE) -> 0.1409 | W12: =VLOOKUP($A12,R_scores!$A:$T,6,FALSE) -> 0.3531 | X12: =VLOOKUP($A12,R_scores!$A:$T,7,FALSE) -> 0.0094 | Y12: =VLOOKUP($A12,R_scores!$A:$T,8,FALSE) -> 0.1033 | Z12: =VLOOKUP($A12,R_scores!$A:$T,9,FALSE) -> 0.1724 | AA12: =VLOOKUP($A12,R_scores!$A:$T,10,FALSE) -> 0.2852 | AB12: =VLOOKUP($A12,R_scores!$A:$T,11,FALSE) -> 0.0697 | AC12: =VLOOKUP($A12,R_scores!$A:$T,12,FALSE) -> -0.0962 | AD12: =VLOOKUP($A12,R_scores!$A:$T,13,FALSE) -> -0.098 | AE12: =VLOOKUP($A12,R_scores!$A:$T,14,FALSE) -> 0.1318 | AF12: =VLOOKUP($A12,R_scores!$A:$T,15,FALSE) -> 0.0729 | AG12: =VLOOKUP($A12,R_scores!$A:$T,16,FALSE) -> -0.352 | AH12: =VLOOKUP($A12,R_scores!$A:$T,17,FALSE) -> 0.0036 | AI12: =VLOOKUP($A12,R_scores!$A:$T,18,FALSE) -> 0.0539 | AJ12: =VLOOKUP($A12,R_scores!$A:$T,19,FALSE) -> -0.0266 | AK12: =VLOOKUP($A12,R_scores!$A:$T,20,FALSE) -> -0.1777 | AL12: =VLOOKUP($A12,DW_avgs_500ns!$A:$HH,COLUMN(C12),FALSE) -> 0 | AM12: =VLOOKUP($A12,DW_avgs_500ns!$A:$HH,COLUMN(D12),FALSE) -> 0 | AN12: =VLOOKUP($A12,DW_avgs_500ns!$A:$HH,COLUMN(E12),FALSE) -> 0 | AO12: =VLOOKUP($A12,DW_avgs_500ns!$A:$HH,COLUMN(F12),FALSE) -> 0 | AP12: =VLOOKUP($A12,DW_avgs_500ns!$A:$HH,COLUMN(G12),FALSE) -> 0 | AQ12: =VLOOKUP($A12,DW_avgs_500ns!$A:$HH,COLUMN(H12),FALSE) -> 0 | AR12: =VLOOKUP($A12,DW_avgs_500ns!$A:$HH,COLUMN(I12),FALSE) -> 0 | AS12: =VLOOKUP($A12,DW_avgs_500ns!$A:$HH,COLUMN(J12),FALSE) -> 0 | ... IQ12: =VLOOKUP($A12,DW_avgs_500ns!$A:$HH,COLUMN(HH12),FALSE) -> 0 | IR12: =VLOOKUP(A12,pkt_vol!A:H,COLUMN(C12),FALSE) -> 957.4819157088123 | IS12: =VLOOKUP($A12,pkt_vol!A:H,COLUMN(D12),FALSE) -> 127.21301328262565 | IT12: =VLOOKUP($A12,pkt_vol!A:H,COLUMN(G12),FALSE) -> 0.080052172 | IU12: =VLOOKUP($A12,lig_contacts!$A:$U,COLUMN(B12),FALSE) -> 14.071818700578788 | IV12: =VLOOKUP($A12,lig_contacts!$A:$U,COLUMN(C12),FALSE) -> 2.2579213517271404 | IW12: =VLOOKUP($A12,lig_contacts!$A:$U,COLUMN(D12),FALSE) -> 1 | IX12: =VLOOKUP($A12,lig_contacts!$A:$U,COLUMN(E12),FALSE) -> 2.0919540229885056 | IY12: =VLOOKUP($A12,lig_contacts!$A:$U,COLUMN(F12),FALSE) -> 0.6722847081335154 | IZ12: =VLOOKUP($A12,lig_contacts!$A:$U,COLUMN(G12),FALSE) -> 0.9991848047607402 | JA12: =VLOOKUP($A12,lig_contacts!$A:$U,COLUMN(H12),FALSE) -> 1.6677264204777045 | JB12: =VLOOKUP($A12,lig_contacts!$A:$U,COLUMN(I12),FALSE) -> 0.9282419251708196 | ... JN12: =VLOOKUP($A12,lig_contacts!$A:$U,COLUMN(U12),FALSE) -> 0.052870215 | JO12: 2.396 | JP12: 1.353 | JQ12: 0.8300000000000001 | JR12: 2.313
A13: pair_3059_binder | B13: 3059 | C13: binder | D13: =IF(C13="Binder", 1,0) -> 1 | E13: 0.2222 | F13: MASELTPEERSELKNSIAEFHTYQLDPGSCSSLHAQRIHAPPELVWSIVRRFDKPQTYVHFIKSCSVEQNFEMRVGCTRDLIAISGLPANTATERLDILDDERRVTGASVIGGEHRLTNLKWVTTVHRFEKENRIWTVVLRSYVVDMPEGNSEDDTRMHVDTLFKLGLQKLATVAEAMARN | G13: 0.396 | H13: 0.0863 | I13: 0.619 | J13: 0.1529 | K13: 0.6749 | L13: 0.1384 | M13: 0.6383 | N13: 0.1771 | O13: 10.7796 | P13: 1.077 | Q13: 7.95 | R13: 21.52 | S13: 70.53 | T13: =VLOOKUP(A13,R_scores!A:T,3,FALSE) -> -0.002 | U13: =VLOOKUP($A13,R_scores!$A:$T,4,FALSE) -> 0.2214 | V13: =VLOOKUP($A13,R_scores!$A:$T,5,FALSE) -> 0.2156 | W13: =VLOOKUP($A13,R_scores!$A:$T,6,FALSE) -> 0.0019 | X13: =VLOOKUP($A13,R_scores!$A:$T,7,FALSE) -> 0.0187 | Y13: =VLOOKUP($A13,R_scores!$A:$T,8,FALSE) -> 0.0287 | Z13: =VLOOKUP($A13,R_scores!$A:$T,9,FALSE) -> 0.2844 | AA13: =VLOOKUP($A13,R_scores!$A:$T,10,FALSE) -> 0.2951 | AB13: =VLOOKUP($A13,R_scores!$A:$T,11,FALSE) -> -0.0038 | AC13: =VLOOKUP($A13,R_scores!$A:$T,12,FALSE) -> -0.0205 | AD13: =VLOOKUP($A13,R_scores!$A:$T,13,FALSE) -> -0.061 | AE13: =VLOOKUP($A13,R_scores!$A:$T,14,FALSE) -> 0.1916 | AF13: =VLOOKUP($A13,R_scores!$A:$T,15,FALSE) -> 0.3826 | AG13: =VLOOKUP($A13,R_scores!$A:$T,16,FALSE) -> -0.046 | AH13: =VLOOKUP($A13,R_scores!$A:$T,17,FALSE) -> -0.0241 | AI13: =VLOOKUP($A13,R_scores!$A:$T,18,FALSE) -> 0.0785 | AJ13: =VLOOKUP($A13,R_scores!$A:$T,19,FALSE) -> 0.3889 | AK13: =VLOOKUP($A13,R_scores!$A:$T,20,FALSE) -> 0.2931 | AL13: =VLOOKUP($A13,DW_avgs_500ns!$A:$HH,COLUMN(C13),FALSE) -> 0 | AM13: =VLOOKUP($A13,DW_avgs_500ns!$A:$HH,COLUMN(D13),FALSE) -> 0 | AN13: =VLOOKUP($A13,DW_avgs_500ns!$A:$HH,COLUMN(E13),FALSE) -> 0 | AO13: =VLOOKUP($A13,DW_avgs_500ns!$A:$HH,COLUMN(F13),FALSE) -> 0 | AP13: =VLOOKUP($A13,DW_avgs_500ns!$A:$HH,COLUMN(G13),FALSE) -> 0 | AQ13: =VLOOKUP($A13,DW_avgs_500ns!$A:$HH,COLUMN(H13),FALSE) -> 0 | AR13: =VLOOKUP($A13,DW_avgs_500ns!$A:$HH,COLUMN(I13),FALSE) -> 0 | AS13: =VLOOKUP($A13,DW_avgs_500ns!$A:$HH,COLUMN(J13),FALSE) -> 0.0155 | ... IQ13: =VLOOKUP($A13,DW_avgs_500ns!$A:$HH,COLUMN(HH13),FALSE) -> 0 | IR13: =VLOOKUP(A13,pkt_vol!A:H,COLUMN(C13),FALSE) -> 906.1267082416239 | IS13: =VLOOKUP($A13,pkt_vol!A:H,COLUMN(D13),FALSE) -> 120.97805729176432 | IT13: =VLOOKUP($A13,pkt_vol!A:H,COLUMN(G13),FALSE) -> 0.16850085595500122 | IU13: =VLOOKUP($A13,lig_contacts!$A:$U,COLUMN(B13),FALSE) -> 14.835982717860928 | IV13: =VLOOKUP($A13,lig_contacts!$A:$U,COLUMN(C13),FALSE) -> 1.9509347365197287 | IW13: =VLOOKUP($A13,lig_contacts!$A:$U,COLUMN(D13),FALSE) -> 1 | IX13: =VLOOKUP($A13,lig_contacts!$A:$U,COLUMN(E13),FALSE) -> 1.6560691285562892 | IY13: =VLOOKUP($A13,lig_contacts!$A:$U,COLUMN(F13),FALSE) -> 0.80897165 | IZ13: =VLOOKUP($A13,lig_contacts!$A:$U,COLUMN(G13),FALSE) -> 0.8754381674411021 | JA13: =VLOOKUP($A13,lig_contacts!$A:$U,COLUMN(H13),FALSE) -> 2.9852449661693976 | JB13: =VLOOKUP($A13,lig_contacts!$A:$U,COLUMN(I13),FALSE) -> 0.9421313199626202 | ... JN13: =VLOOKUP($A13,lig_contacts!$A:$U,COLUMN(U13),FALSE) -> 0.056255059 | JO13: 1.081 | JP13: 0.6379999999999999 | JQ13: 1.086 | JR13: 1.5379999999999998
A14: pair_3062_binder | B14: 3062 | C14: binder | D14: =IF(C14="Binder", 1,0) -> 1 | E14: 0.8794 | F14: MASELTPEERSELKNSIAEFHTYQLDPGSCSSLHAQRIHAPPELVWSIVRRFDKPQTYVHFIKSCSVEQNFEMRVGCTRDDILISGLPANTMTVRLDILDDERRVTGASVIGGEHRVTNLKTVTTVHRFEKENRIWTVVLKSYVVDMPEGNSEDDTRMIVDTGVKLLLQKLATVAEAMARN | G14: 0.2899 | H14: 0.0386 | I14: 0.3612 | J14: 0.0917 | K14: 0.6691 | L14: 0.1148 | M14: 0.5425 | N14: 0.108 | O14: 8.7093 | P14: 0.7099 | Q14: 87.87 | R14: 0.46 | S14: 11.67 | T14: =VLOOKUP(A14,R_scores!A:T,3,FALSE) -> -0.0074 | U14: =VLOOKUP($A14,R_scores!$A:$T,4,FALSE) -> -0.0418 | V14: =VLOOKUP($A14,R_scores!$A:$T,5,FALSE) -> -0.2144 | W14: =VLOOKUP($A14,R_scores!$A:$T,6,FALSE) -> 0.418 | X14: =VLOOKUP($A14,R_scores!$A:$T,7,FALSE) -> 0.0959 | Y14: =VLOOKUP($A14,R_scores!$A:$T,8,FALSE) -> 0.2348 | Z14: =VLOOKUP($A14,R_scores!$A:$T,9,FALSE) -> 0.151 | AA14: =VLOOKUP($A14,R_scores!$A:$T,10,FALSE) -> -0.3559 | AB14: =VLOOKUP($A14,R_scores!$A:$T,11,FALSE) -> -0.0448 | AC14: =VLOOKUP($A14,R_scores!$A:$T,12,FALSE) -> -0.2081 | AD14: =VLOOKUP($A14,R_scores!$A:$T,13,FALSE) -> -0.223 | AE14: =VLOOKUP($A14,R_scores!$A:$T,14,FALSE) -> 0.1474 | AF14: =VLOOKUP($A14,R_scores!$A:$T,15,FALSE) -> 0.0632 | AG14: =VLOOKUP($A14,R_scores!$A:$T,16,FALSE) -> 0.0653 | AH14: =VLOOKUP($A14,R_scores!$A:$T,17,FALSE) -> 0.1921 | AI14: =VLOOKUP($A14,R_scores!$A:$T,18,FALSE) -> 0.1793 | AJ14: =VLOOKUP($A14,R_scores!$A:$T,19,FALSE) -> 0.0967 | AK14: =VLOOKUP($A14,R_scores!$A:$T,20,FALSE) -> 0.0051 | AL14: =VLOOKUP($A14,DW_avgs_500ns!$A:$HH,COLUMN(C14),FALSE) -> 0 | AM14: =VLOOKUP($A14,DW_avgs_500ns!$A:$HH,COLUMN(D14),FALSE) -> 0 | AN14: =VLOOKUP($A14,DW_avgs_500ns!$A:$HH,COLUMN(E14),FALSE) -> 0 | AO14: =VLOOKUP($A14,DW_avgs_500ns!$A:$HH,COLUMN(F14),FALSE) -> 0 | AP14: =VLOOKUP($A14,DW_avgs_500ns!$A:$HH,COLUMN(G14),FALSE) -> 0 | AQ14: =VLOOKUP($A14,DW_avgs_500ns!$A:$HH,COLUMN(H14),FALSE) -> 0 | AR14: =VLOOKUP($A14,DW_avgs_500ns!$A:$HH,COLUMN(I14),FALSE) -> 0 | AS14: =VLOOKUP($A14,DW_avgs_500ns!$A:$HH,COLUMN(J14),FALSE) -> 0 | ... IQ14: =VLOOKUP($A14,DW_avgs_500ns!$A:$HH,COLUMN(HH14),FALSE) -> 0 | IR14: =VLOOKUP(A14,pkt_vol!A:H,COLUMN(C14),FALSE) -> 958.86902 | IS14: =VLOOKUP($A14,pkt_vol!A:H,COLUMN(D14),FALSE) -> 111.38144847435714 | IT14: =VLOOKUP($A14,pkt_vol!A:H,COLUMN(G14),FALSE) -> 0.081927122 | IU14: =VLOOKUP($A14,lig_contacts!$A:$U,COLUMN(B14),FALSE) -> 15.35061547240564 | IV14: =VLOOKUP($A14,lig_contacts!$A:$U,COLUMN(C14),FALSE) -> 1.494016839666613 | IW14: =VLOOKUP($A14,lig_contacts!$A:$U,COLUMN(D14),FALSE) -> 1 | IX14: =VLOOKUP($A14,lig_contacts!$A:$U,COLUMN(E14),FALSE) -> 1.182440694546344 | IY14: =VLOOKUP($A14,lig_contacts!$A:$U,COLUMN(F14),FALSE) -> 0.5315280130554694 | IZ14: =VLOOKUP($A14,lig_contacts!$A:$U,COLUMN(G14),FALSE) -> 0.9910328523681422 | JA14: =VLOOKUP($A14,lig_contacts!$A:$U,COLUMN(H14),FALSE) -> 2.2677916360968453 | JB14: =VLOOKUP($A14,lig_contacts!$A:$U,COLUMN(I14),FALSE) -> 0.9604260689474772 | ... JN14: =VLOOKUP($A14,lig_contacts!$A:$U,COLUMN(U14),FALSE) -> 0.052308029 | JO14: 1.786 | JP14: 0.679 | JQ14: 0.609 | JR14: 0.916
A15: pair_3063_binder | B15: 3063 | C15: binder | D15: =IF(C15="Binder", 1,0) -> 1 | E15: 0.8421 | F15: MASELTPEERSELKNSIAEFHTYQLDPGSCSSLHAQRIHAPPELVWSIVRRFDKPQTYAHFIKSCSVEQNFEMRVGCTRDDILISGLPANTMTVRLDILDDERRVTGASVIGGEHRVTNLKTVTTVHRFEKENRIWTVVLKSYVVDMPEGNSEDDTRMIMDTGIKLILQKLATVAEAMARN | G15: 0.3517 | H15: 0.0667 | I15: 0.4992 | J15: 0.125 | K15: 0.7049 | L15: 0.1695 | M15: 0.6195 | N15: 0.1486 | O15: 12.5979 | P15: 2.2921 | Q15: 6.14 | R15: 58.17 | S15: 35.69 | T15: =VLOOKUP(A15,R_scores!A:T,3,FALSE) -> -0.0375 | U15: =VLOOKUP($A15,R_scores!$A:$T,4,FALSE) -> 0.065 | V15: =VLOOKUP($A15,R_scores!$A:$T,5,FALSE) -> 0.0002 | W15: =VLOOKUP($A15,R_scores!$A:$T,6,FALSE) -> 0.1054 | X15: =VLOOKUP($A15,R_scores!$A:$T,7,FALSE) -> 0.0186 | Y15: =VLOOKUP($A15,R_scores!$A:$T,8,FALSE) -> -0.0278 | Z15: =VLOOKUP($A15,R_scores!$A:$T,9,FALSE) -> -0.0344 | AA15: =VLOOKUP($A15,R_scores!$A:$T,10,FALSE) -> 0.169 | AB15: =VLOOKUP($A15,R_scores!$A:$T,11,FALSE) -> -0.1338 | AC15: =VLOOKUP($A15,R_scores!$A:$T,12,FALSE) -> -0.0139 | AD15: =VLOOKUP($A15,R_scores!$A:$T,13,FALSE) -> -0.0002 | AE15: =VLOOKUP($A15,R_scores!$A:$T,14,FALSE) -> -0.0199 | AF15: =VLOOKUP($A15,R_scores!$A:$T,15,FALSE) -> 0.0939 | AG15: =VLOOKUP($A15,R_scores!$A:$T,16,FALSE) -> -0.0491 | AH15: =VLOOKUP($A15,R_scores!$A:$T,17,FALSE) -> -0.0778 | AI15: =VLOOKUP($A15,R_scores!$A:$T,18,FALSE) -> 0.3949 | AJ15: =VLOOKUP($A15,R_scores!$A:$T,19,FALSE) -> 0.2155 | AK15: =VLOOKUP($A15,R_scores!$A:$T,20,FALSE) -> 0.1381 | AL15: =VLOOKUP($A15,DW_avgs_500ns!$A:$HH,COLUMN(C15),FALSE) -> 0 | AM15: =VLOOKUP($A15,DW_avgs_500ns!$A:$HH,COLUMN(D15),FALSE) -> 0 | AN15: =VLOOKUP($A15,DW_avgs_500ns!$A:$HH,COLUMN(E15),FALSE) -> 0 | AO15: =VLOOKUP($A15,DW_avgs_500ns!$A:$HH,COLUMN(F15),FALSE) -> 0.0261 | AP15: =VLOOKUP($A15,DW_avgs_500ns!$A:$HH,COLUMN(G15),FALSE) -> 0 | AQ15: =VLOOKUP($A15,DW_avgs_500ns!$A:$HH,COLUMN(H15),FALSE) -> 0.0057 | AR15: =VLOOKUP($A15,DW_avgs_500ns!$A:$HH,COLUMN(I15),FALSE) -> 0.0196 | AS15: =VLOOKUP($A15,DW_avgs_500ns!$A:$HH,COLUMN(J15),FALSE) -> 0.1752 | ... IQ15: =VLOOKUP($A15,DW_avgs_500ns!$A:$HH,COLUMN(HH15),FALSE) -> 0 | IR15: =VLOOKUP(A15,pkt_vol!A:H,COLUMN(C15),FALSE) -> 896.6254707752507 | IS15: =VLOOKUP($A15,pkt_vol!A:H,COLUMN(D15),FALSE) -> 135.19807924448392 | IT15: =VLOOKUP($A15,pkt_vol!A:H,COLUMN(G15),FALSE) -> 0.2073856688676938 | IU15: =VLOOKUP($A15,lig_contacts!$A:$U,COLUMN(B15),FALSE) -> 11.773864840629331 | IV15: =VLOOKUP($A15,lig_contacts!$A:$U,COLUMN(C15),FALSE) -> 1.736415348540845 | IW15: =VLOOKUP($A15,lig_contacts!$A:$U,COLUMN(D15),FALSE) -> 1 | IX15: =VLOOKUP($A15,lig_contacts!$A:$U,COLUMN(E15),FALSE) -> 2.2546669927447622 | IY15: =VLOOKUP($A15,lig_contacts!$A:$U,COLUMN(F15),FALSE) -> 1.1877070791514976 | IZ15: =VLOOKUP($A15,lig_contacts!$A:$U,COLUMN(G15),FALSE) -> 0.9851634466454716 | JA15: =VLOOKUP($A15,lig_contacts!$A:$U,COLUMN(H15),FALSE) -> 2.290535583272194 | JB15: =VLOOKUP($A15,lig_contacts!$A:$U,COLUMN(I15),FALSE) -> 0.7441262716402773 | ... JN15: =VLOOKUP($A15,lig_contacts!$A:$U,COLUMN(U15),FALSE) -> 0.071411232 | JO15: 1.6500000000000001 | JP15: 1.2690000000000001 | JQ15: 0.9909999999999999 | JR15: 2.06
A16: pair_3066_binder | B16: 3066 | C16: binder | D16: =IF(C16="Binder", 1,0) -> 1 | E16: 0.7959 | F16: MASELTPEERSELKNSIAEFHTYQLDPGSCSSLHAQRIHAPPELVWSIVRRFDKPQTYVHFIKSCSVEQNFEMRVGCTRDDILISGLPANTMTLRLDILDDERRVTGASVIGGEHRVTNLKTVTTVHRFEKENRIWTVVLKSYVVDMPEGNSEDDTRMIMDTGIKLILQKLATVAEAMARN | G16: 0.4759 | H16: 0.1303 | I16: 0.4878 | J16: 0.0674 | K16: 0.7135 | L16: 0.1271 | M16: 0.4548 | N16: 0.097 | O16: 10.9073 | P16: 1.5809 | Q16: 19.67 | R16: 36.81 | S16: 43.52 | T16: =VLOOKUP(A16,R_scores!A:T,3,FALSE) -> -0.2159 | U16: =VLOOKUP($A16,R_scores!$A:$T,4,FALSE) -> 0.0143 | V16: =VLOOKUP($A16,R_scores!$A:$T,5,FALSE) -> -0.1826 | W16: =VLOOKUP($A16,R_scores!$A:$T,6,FALSE) -> 0.2362 | X16: =VLOOKUP($A16,R_scores!$A:$T,7,FALSE) -> 0.0303 | Y16: =VLOOKUP($A16,R_scores!$A:$T,8,FALSE) -> -0.0514 | Z16: =VLOOKUP($A16,R_scores!$A:$T,9,FALSE) -> 0.1035 | AA16: =VLOOKUP($A16,R_scores!$A:$T,10,FALSE) -> -0.0242 | AB16: =VLOOKUP($A16,R_scores!$A:$T,11,FALSE) -> 0.0032 | AC16: =VLOOKUP($A16,R_scores!$A:$T,12,FALSE) -> 0.2535 | AD16: =VLOOKUP($A16,R_scores!$A:$T,13,FALSE) -> 0.0256 | AE16: =VLOOKUP($A16,R_scores!$A:$T,14,FALSE) -> 0.1323 | AF16: =VLOOKUP($A16,R_scores!$A:$T,15,FALSE) -> 0.0925 | AG16: =VLOOKUP($A16,R_scores!$A:$T,16,FALSE) -> 0.2571 | AH16: =VLOOKUP($A16,R_scores!$A:$T,17,FALSE) -> 0.0427 | AI16: =VLOOKUP($A16,R_scores!$A:$T,18,FALSE) -> 0.3364 | AJ16: =VLOOKUP($A16,R_scores!$A:$T,19,FALSE) -> -0.0119 | AK16: =VLOOKUP($A16,R_scores!$A:$T,20,FALSE) -> 0.1528 | AL16: =VLOOKUP($A16,DW_avgs_500ns!$A:$HH,COLUMN(C16),FALSE) -> 0 | AM16: =VLOOKUP($A16,DW_avgs_500ns!$A:$HH,COLUMN(D16),FALSE) -> 0 | AN16: =VLOOKUP($A16,DW_avgs_500ns!$A:$HH,COLUMN(E16),FALSE) -> 0 | AO16: =VLOOKUP($A16,DW_avgs_500ns!$A:$HH,COLUMN(F16),FALSE) -> 0 | AP16: =VLOOKUP($A16,DW_avgs_500ns!$A:$HH,COLUMN(G16),FALSE) -> 0 | AQ16: =VLOOKUP($A16,DW_avgs_500ns!$A:$HH,COLUMN(H16),FALSE) -> 0 | AR16: =VLOOKUP($A16,DW_avgs_500ns!$A:$HH,COLUMN(I16),FALSE) -> 0 | AS16: =VLOOKUP($A16,DW_avgs_500ns!$A:$HH,COLUMN(J16),FALSE) -> 0 | ... IQ16: =VLOOKUP($A16,DW_avgs_500ns!$A:$HH,COLUMN(HH16),FALSE) -> 0 | IR16: =VLOOKUP(A16,pkt_vol!A:H,COLUMN(C16),FALSE) -> 985.7755930545366 | IS16: =VLOOKUP($A16,pkt_vol!A:H,COLUMN(D16),FALSE) -> 107.79741771563003 | IT16: =VLOOKUP($A16,pkt_vol!A:H,COLUMN(G16),FALSE) -> 0.058612538 | IU16: =VLOOKUP($A16,lig_contacts!$A:$U,COLUMN(B16),FALSE) -> 13.709545936251732 | IV16: =VLOOKUP($A16,lig_contacts!$A:$U,COLUMN(C16),FALSE) -> 1.584965234135599 | IW16: =VLOOKUP($A16,lig_contacts!$A:$U,COLUMN(D16),FALSE) -> 1 | IX16: =VLOOKUP($A16,lig_contacts!$A:$U,COLUMN(E16),FALSE) -> 1.359664139561425 | IY16: =VLOOKUP($A16,lig_contacts!$A:$U,COLUMN(F16),FALSE) -> 0.8321787950526456 | IZ16: =VLOOKUP($A16,lig_contacts!$A:$U,COLUMN(G16),FALSE) -> 0.9925817233227358 | JA16: =VLOOKUP($A16,lig_contacts!$A:$U,COLUMN(H16),FALSE) -> 2.3459688595418604 | JB16: =VLOOKUP($A16,lig_contacts!$A:$U,COLUMN(I16),FALSE) -> 0.6883078398568775 | ... JN16: =VLOOKUP($A16,lig_contacts!$A:$U,COLUMN(U16),FALSE) -> 0.04252851 | JO16: 3.406 | JP16: 1.081 | JQ16: 0.877 | JR16: 0.7040000000000001
A17: pair_3067_binder | B17: 3067 | C17: binder | D17: =IF(C17="Binder", 1,0) -> 1 | E17: 0.7921 | F17: MASELTPEERSELKNSIAEFHTYQLDPGSCSSLHAQRIHAPPELVWSIVRRFDKPQTYVHFIKSCSVEQNFEMRVGCTRDDILISGLPANTMTVRLDILDDERRVTGASVIGGEHRVTNLKTVTTVHRFEKENRIWTVVLKSYVVDMPEGNSEDDTRMILDTGYKLILQKLATVAEAMARN | G17: 0.475 | H17: 0.1329 | I17: 0.4872 | J17: 0.0684 | K17: 0.713 | L17: 0.1296 | M17: 0.4535 | N17: 0.1004 | O17: 10.9073 | P17: 1.5809 | Q17: 19.67 | R17: 36.81 | S17: 43.52 | T17: =VLOOKUP(A17,R_scores!A:T,3,FALSE) -> 0 | U17: =VLOOKUP($A17,R_scores!$A:$T,4,FALSE) -> 0.0529 | V17: =VLOOKUP($A17,R_scores!$A:$T,5,FALSE) -> -0.0455 | W17: =VLOOKUP($A17,R_scores!$A:$T,6,FALSE) -> 0.7282 | X17: =VLOOKUP($A17,R_scores!$A:$T,7,FALSE) -> 0.0283 | Y17: =VLOOKUP($A17,R_scores!$A:$T,8,FALSE) -> -0.1852 | Z17: =VLOOKUP($A17,R_scores!$A:$T,9,FALSE) -> -0.0057 | AA17: =VLOOKUP($A17,R_scores!$A:$T,10,FALSE) -> 0.718 | AB17: =VLOOKUP($A17,R_scores!$A:$T,11,FALSE) -> 0.2832 | AC17: =VLOOKUP($A17,R_scores!$A:$T,12,FALSE) -> -0.0759 | AD17: =VLOOKUP($A17,R_scores!$A:$T,13,FALSE) -> -0.1562 | AE17: =VLOOKUP($A17,R_scores!$A:$T,14,FALSE) -> -0.0784 | AF17: =VLOOKUP($A17,R_scores!$A:$T,15,FALSE) -> 0.14 | AG17: =VLOOKUP($A17,R_scores!$A:$T,16,FALSE) -> -0.1775 | AH17: =VLOOKUP($A17,R_scores!$A:$T,17,FALSE) -> -0.1636 | AI17: =VLOOKUP($A17,R_scores!$A:$T,18,FALSE) -> 0.6858 | AJ17: =VLOOKUP($A17,R_scores!$A:$T,19,FALSE) -> 0.2356 | AK17: =VLOOKUP($A17,R_scores!$A:$T,20,FALSE) -> 0.2423 | AL17: =VLOOKUP($A17,DW_avgs_500ns!$A:$HH,COLUMN(C17),FALSE) -> 0 | AM17: =VLOOKUP($A17,DW_avgs_500ns!$A:$HH,COLUMN(D17),FALSE) -> 0 | AN17: =VLOOKUP($A17,DW_avgs_500ns!$A:$HH,COLUMN(E17),FALSE) -> 0 | AO17: =VLOOKUP($A17,DW_avgs_500ns!$A:$HH,COLUMN(F17),FALSE) -> 0 | AP17: =VLOOKUP($A17,DW_avgs_500ns!$A:$HH,COLUMN(G17),FALSE) -> 0 | AQ17: =VLOOKUP($A17,DW_avgs_500ns!$A:$HH,COLUMN(H17),FALSE) -> 0 | AR17: =VLOOKUP($A17,DW_avgs_500ns!$A:$HH,COLUMN(I17),FALSE) -> 0 | AS17: =VLOOKUP($A17,DW_avgs_500ns!$A:$HH,COLUMN(J17),FALSE) -> 0 | ... IQ17: =VLOOKUP($A17,DW_avgs_500ns!$A:$HH,COLUMN(HH17),FALSE) -> 0 | IR17: =VLOOKUP(A17,pkt_vol!A:H,COLUMN(C17),FALSE) -> 1016.483819189696 | IS17: =VLOOKUP($A17,pkt_vol!A:H,COLUMN(D17),FALSE) -> 132.25378299204317 | IT17: =VLOOKUP($A17,pkt_vol!A:H,COLUMN(G17),FALSE) -> 0.065786256 | IU17: =VLOOKUP($A17,lig_contacts!$A:$U,COLUMN(B17),FALSE) -> 12.715822939594032 | IV17: =VLOOKUP($A17,lig_contacts!$A:$U,COLUMN(C17),FALSE) -> 1.2617543458614036 | IW17: =VLOOKUP($A17,lig_contacts!$A:$U,COLUMN(D17),FALSE) -> 1 | IX17: =VLOOKUP($A17,lig_contacts!$A:$U,COLUMN(E17),FALSE) -> 1.943670008967148 | IY17: =VLOOKUP($A17,lig_contacts!$A:$U,COLUMN(F17),FALSE) -> 0.2791753184230102 | IZ17: =VLOOKUP($A17,lig_contacts!$A:$U,COLUMN(G17),FALSE) -> 0.9983696095214804 | JA17: =VLOOKUP($A17,lig_contacts!$A:$U,COLUMN(H17),FALSE) -> 2.0079073938208203 | JB17: =VLOOKUP($A17,lig_contacts!$A:$U,COLUMN(I17),FALSE) -> 0.7083008844321536 | ... JN17: =VLOOKUP($A17,lig_contacts!$A:$U,COLUMN(U17),FALSE) -> 0.037894866 | JO17: 1.958 | JP17: 0.994 | JQ17: 0.8350000000000001 | JR17: 0.782
A18: pair_3068_binder | B18: 3068 | C18: binder | D18: =IF(C18="Binder", 1,0) -> 1 | E18: 0.7813 | F18: MASELTPEERSELKNSIAEFHTYQLDPGSCSSLHAQRIHAPPELVWSIVRRFDKPQTYVHFIKSCSVEQNFEMRVGCTRDDILISGLPANTMTVRLDILDDERRVTGASVIGGEHRVTNLKTVTTVHRFEKENRIWTVVLKSYVVDMPEGNSEDDTRMILDTGVKLILQKLATVAEAMARN | G18: 0.3753 | H18: 0.089 | I18: 0.3828 | J18: 0.1035 | K18: 0.6964 | L18: 0.143 | M18: 0.4487 | N18: 0.1447 | O18: 10.658 | P18: 1.4066 | Q18: 18.59 | R18: 22.58 | S18: 58.83 | T18: =VLOOKUP(A18,R_scores!A:T,3,FALSE) -> -0.1708 | U18: =VLOOKUP($A18,R_scores!$A:$T,4,FALSE) -> -0.2239 | V18: =VLOOKUP($A18,R_scores!$A:$T,5,FALSE) -> 0.0247 | W18: =VLOOKUP($A18,R_scores!$A:$T,6,FALSE) -> 0.3502 | X18: =VLOOKUP($A18,R_scores!$A:$T,7,FALSE) -> 0.0803 | Y18: =VLOOKUP($A18,R_scores!$A:$T,8,FALSE) -> -0.1287 | Z18: =VLOOKUP($A18,R_scores!$A:$T,9,FALSE) -> 0.1489 | AA18: =VLOOKUP($A18,R_scores!$A:$T,10,FALSE) -> 0.0386 | AB18: =VLOOKUP($A18,R_scores!$A:$T,11,FALSE) -> -0.0317 | AC18: =VLOOKUP($A18,R_scores!$A:$T,12,FALSE) -> -0.008 | AD18: =VLOOKUP($A18,R_scores!$A:$T,13,FALSE) -> -0.3321 | AE18: =VLOOKUP($A18,R_scores!$A:$T,14,FALSE) -> -0.0405 | AF18: =VLOOKUP($A18,R_scores!$A:$T,15,FALSE) -> 0.0626 | AG18: =VLOOKUP($A18,R_scores!$A:$T,16,FALSE) -> 0.2484 | AH18: =VLOOKUP($A18,R_scores!$A:$T,17,FALSE) -> 0.0997 | AI18: =VLOOKUP($A18,R_scores!$A:$T,18,FALSE) -> 0.4291 | AJ18: =VLOOKUP($A18,R_scores!$A:$T,19,FALSE) -> 0.0709 | AK18: =VLOOKUP($A18,R_scores!$A:$T,20,FALSE) -> 0.1571 | AL18: =VLOOKUP($A18,DW_avgs_500ns!$A:$HH,COLUMN(C18),FALSE) -> 0 | AM18: =VLOOKUP($A18,DW_avgs_500ns!$A:$HH,COLUMN(D18),FALSE) -> 0 | AN18: =VLOOKUP($A18,DW_avgs_500ns!$A:$HH,COLUMN(E18),FALSE) -> 0 | AO18: =VLOOKUP($A18,DW_avgs_500ns!$A:$HH,COLUMN(F18),FALSE) -> 0 | AP18: =VLOOKUP($A18,DW_avgs_500ns!$A:$HH,COLUMN(G18),FALSE) -> 0 | AQ18: =VLOOKUP($A18,DW_avgs_500ns!$A:$HH,COLUMN(H18),FALSE) -> 0 | AR18: =VLOOKUP($A18,DW_avgs_500ns!$A:$HH,COLUMN(I18),FALSE) -> 0 | AS18: =VLOOKUP($A18,DW_avgs_500ns!$A:$HH,COLUMN(J18),FALSE) -> 0 | ... IQ18: =VLOOKUP($A18,DW_avgs_500ns!$A:$HH,COLUMN(HH18),FALSE) -> 0 | IR18: =VLOOKUP(A18,pkt_vol!A:H,COLUMN(C18),FALSE) -> 1009.1963414037662 | IS18: =VLOOKUP($A18,pkt_vol!A:H,COLUMN(D18),FALSE) -> 140.39619461252448 | IT18: =VLOOKUP($A18,pkt_vol!A:H,COLUMN(G18),FALSE) -> 0.081111926 | IU18: =VLOOKUP($A18,lig_contacts!$A:$U,COLUMN(B18),FALSE) -> 12.420477704410208 | IV18: =VLOOKUP($A18,lig_contacts!$A:$U,COLUMN(C18),FALSE) -> 1.5093841401872303 | IW18: =VLOOKUP($A18,lig_contacts!$A:$U,COLUMN(D18),FALSE) -> 1 | IX18: =VLOOKUP($A18,lig_contacts!$A:$U,COLUMN(E18),FALSE) -> 2.112496943017853 | IY18: =VLOOKUP($A18,lig_contacts!$A:$U,COLUMN(F18),FALSE) -> 0.8309824614257173 | IZ18: =VLOOKUP($A18,lig_contacts!$A:$U,COLUMN(G18),FALSE) -> 0.9872829542675472 | JA18: =VLOOKUP($A18,lig_contacts!$A:$U,COLUMN(H18),FALSE) -> 2.6226461237466374 | JB18: =VLOOKUP($A18,lig_contacts!$A:$U,COLUMN(I18),FALSE) -> 0.7812002409658727 | ... JN18: =VLOOKUP($A18,lig_contacts!$A:$U,COLUMN(U18),FALSE) -> 0.053445952 | JO18: 1.601 | JP18: 0.777 | JQ18: 0.9550000000000001 | JR18: 0.6769999999999999
A19: pair_3071_binder | B19: 3071 | C19: binder | D19: =IF(C19="Binder", 1,0) -> 1 | E19: 0.7561 | F19: MASELTPEERSELKNSIAEFHTYQLDPGSCSSLHAQRIHAPPELVWSIVRRFDKPQTYVHFIKSCSVEQNFEMRVGCTRDDILISGLPANTMTLRLDILDDERRVTGASVIGGEHRVTNLKTVTTVHRFEKENRIWTVVLKSYVVDMPEGNSEDDTRMILDTGVKLILQKLATVAEAMARN | G19: 0.3441 | H19: 0.0585 | I19: 0.5026 | J19: 0.1615 | K19: 0.6524 | L19: 0.1023 | M19: 0.3342 | N19: 0.0672 | O19: 7.7319 | P19: 1.3544 | Q19: 88.53 | R19: 1.31 | S19: 10.15 | T19: =VLOOKUP(A19,R_scores!A:T,3,FALSE) -> -0.0672 | U19: =VLOOKUP($A19,R_scores!$A:$T,4,FALSE) -> 0.1874 | V19: =VLOOKUP($A19,R_scores!$A:$T,5,FALSE) -> 0.0865 | W19: =VLOOKUP($A19,R_scores!$A:$T,6,FALSE) -> 0.3275 | X19: =VLOOKUP($A19,R_scores!$A:$T,7,FALSE) -> 0.0912 | Y19: =VLOOKUP($A19,R_scores!$A:$T,8,FALSE) -> 0.1229 | Z19: =VLOOKUP($A19,R_scores!$A:$T,9,FALSE) -> 0.1082 | AA19: =VLOOKUP($A19,R_scores!$A:$T,10,FALSE) -> 0.3127 | AB19: =VLOOKUP($A19,R_scores!$A:$T,11,FALSE) -> -0.0014 | AC19: =VLOOKUP($A19,R_scores!$A:$T,12,FALSE) -> -0.0123 | AD19: =VLOOKUP($A19,R_scores!$A:$T,13,FALSE) -> -0.0225 | AE19: =VLOOKUP($A19,R_scores!$A:$T,14,FALSE) -> -0.0184 | AF19: =VLOOKUP($A19,R_scores!$A:$T,15,FALSE) -> 0.1896 | AG19: =VLOOKUP($A19,R_scores!$A:$T,16,FALSE) -> -0.0408 | AH19: =VLOOKUP($A19,R_scores!$A:$T,17,FALSE) -> 0.0503 | AI19: =VLOOKUP($A19,R_scores!$A:$T,18,FALSE) -> 0.2558 | AJ19: =VLOOKUP($A19,R_scores!$A:$T,19,FALSE) -> -0.0121 | AK19: =VLOOKUP($A19,R_scores!$A:$T,20,FALSE) -> -0.0205 | AL19: =VLOOKUP($A19,DW_avgs_500ns!$A:$HH,COLUMN(C19),FALSE) -> 0 | AM19: =VLOOKUP($A19,DW_avgs_500ns!$A:$HH,COLUMN(D19),FALSE) -> 0 | AN19: =VLOOKUP($A19,DW_avgs_500ns!$A:$HH,COLUMN(E19),FALSE) -> 0 | AO19: =VLOOKUP($A19,DW_avgs_500ns!$A:$HH,COLUMN(F19),FALSE) -> 0 | AP19: =VLOOKUP($A19,DW_avgs_500ns!$A:$HH,COLUMN(G19),FALSE) -> 0 | AQ19: =VLOOKUP($A19,DW_avgs_500ns!$A:$HH,COLUMN(H19),FALSE) -> 0 | AR19: =VLOOKUP($A19,DW_avgs_500ns!$A:$HH,COLUMN(I19),FALSE) -> 0 | AS19: =VLOOKUP($A19,DW_avgs_500ns!$A:$HH,COLUMN(J19),FALSE) -> 0 | ... IQ19: =VLOOKUP($A19,DW_avgs_500ns!$A:$HH,COLUMN(HH19),FALSE) -> 0 | IR19: =VLOOKUP(A19,pkt_vol!A:H,COLUMN(C19),FALSE) -> 992.3658579929894 | IS19: =VLOOKUP($A19,pkt_vol!A:H,COLUMN(D19),FALSE) -> 117.1033416166729 | IT19: =VLOOKUP($A19,pkt_vol!A:H,COLUMN(G19),FALSE) -> 0.061139642944485206 | IU19: =VLOOKUP($A19,lig_contacts!$A:$U,COLUMN(B19),FALSE) -> 13.677997880492375 | IV19: =VLOOKUP($A19,lig_contacts!$A:$U,COLUMN(C19),FALSE) -> 1.7851066241916798 | IW19: =VLOOKUP($A19,lig_contacts!$A:$U,COLUMN(D19),FALSE) -> 1 | IX19: =VLOOKUP($A19,lig_contacts!$A:$U,COLUMN(E19),FALSE) -> 1.4494171354039291 | IY19: =VLOOKUP($A19,lig_contacts!$A:$U,COLUMN(F19),FALSE) -> 1.616268159341742 | IZ19: =VLOOKUP($A19,lig_contacts!$A:$U,COLUMN(G19),FALSE) -> 0.5818863617836472 | JA19: =VLOOKUP($A19,lig_contacts!$A:$U,COLUMN(H19),FALSE) -> 1.6374011575772398 | JB19: =VLOOKUP($A19,lig_contacts!$A:$U,COLUMN(I19),FALSE) -> 0.8314927263557507 | ... JN19: =VLOOKUP($A19,lig_contacts!$A:$U,COLUMN(U19),FALSE) -> 0.071893318 | JO19: 1.081 | JP19: 0.6619999999999999 | JQ19: 0.717 | JR19: 0.8160000000000001
